Workbook
Name VarYok: Listeler!$A$2:$A$3
Name Guncel: Listeler!$B$2:$B$4
Name Uygun: Listeler!$C$2:$C$4
Name Mevcut: Listeler!$D$2:$D$4
Name Mulkiyet: Listeler!$E$2:$E$4
Name CedVar: Listeler!$F$2:$F$4
Name CedTur: Listeler!$G$2:$G$5
Name CedEk: Listeler!$H$2:$H$4
Name Taahhut: Listeler!$I$2:$I$5
Name Degisim: Listeler!$J$2:$J$4
Name IzinGorus: Listeler!$K$2:$K$5
Name IzinEk: Listeler!$L$2:$L$5
Name IzinVar: Listeler!$M$2:$M$5
Name Yenileme: Listeler!$N$2:$N$6
Name Gfb: Listeler!$O$2:$O$4
Name Rapor: Listeler!$P$2:$P$5
Name SifirKontrol: Listeler!$Q$2:$Q$5
Name Beyan: Listeler!$R$2:$R$4
Name Gerekli: Listeler!$S$2:$S$4
Name Gekap: Listeler!$T$2:$T$4
Name BekraKapsam: Listeler!$U$2:$U$4
Name BekraSeviye: Listeler!$V$2:$V$4
Name BekraGuncel: Listeler!$W$2:$W$4
Name HatAyri: Listeler!$X$2:$X$4
Name Kapanis: Listeler!$Y$2:$Y$4
Name Tutanak: Listeler!$Z$2:$Z$4
Name Oncelik: Listeler!$AA$2:$AA$5
Name Dosya: Listeler!$AB$2:$AB$5
Name Siklik: Listeler!$AC$2:$AC$6
Name Iller: Listeler!$AD$2:$AD$82

Sheet Firmalar
A1: ÇEVRE DANIŞMANLIĞI · FİRMA TAKİP PANELİ
A2: Bugün | B2: =TODAY() | C2: =COUNTIF(C5:C44,">0") | D2: firmada açık uyarı | E2: =COUNTIF(H5:H44,"Aktif") | F2: aktif dosya | G2: Her satır bir firmadır. Sağdaki renkli şeritler kapalı bölümdür; üstteki + ile açılır. Mavi sütunlar otomatiktir. En yakın iş, süresi geçen tarihleri öne alır. Sözleşme 60 gün, çevre izni 180 gün, iç tetkik ve eğitim 1 ay, sıfır atık ve atık planı 3 ay, emisyon 45 gün kala uyarır.
A3: Günlük görünüm sabit kalsın diye No'dan Kalan gün'e kadar donduruludur. Yeni firma için alttaki boş satıra yazın; formül bitince satırı kopyalayın.
A4: No | B4: Firma / tesis adı | C4: Aktif uyarı | D4: En yakın iş | E4: En yakın tarih | F4: Kalan gün | G4: Öncelik | H4: Dosya durumu | I4: İl | J4: İlçe | K4: Firma yetkilisi | L4: Yetkili telefon | M4: Yetkili e-posta | N4: Bizim danışman | O4: Öncelikli not | P4: Sözleşme | Q4: İç tetkik | R4: Çevre eğitimi | S4: Sıfır Atık | T4: Atık planı | U4: Emisyon | V4: Çevre izni | W4: Kimlik | X4: Ticari unvan | Y4: Tesis adresi | Z4: Faaliyet konusu | AA4: NACE kodu | AB4: Vergi dairesi | AC4: Vergi numarası | AD4: MERSİS numarası | AE4: ÇKN numarası | AF4: Mülkiyet (kira / tapu) | AG4: Kira / tapu belgesi | AH4: Yetkili unvanı | AI4: Tesis telefon | AJ4: Tesis e-posta | AK4: Sözleşme başlangıç | AL4: Sözleşme bitiş | AM4: Ziyaret sıklığı | AN4: İrtibat / özel not | AO4: Belge | AP4: İş akım şeması | AQ4: İş akım şeması güncel mi | AR4: Vaziyet planı | AS4: Vaziyet planı güncel mi | AT4: Kapasite raporu | AU4: Proses / ekipman listesi | AV4: Tapu / kira belgesi güncel mi | AW4: Faaliyet değişikliği | AX4: İzin | AY4: ÇED görüşü / kararı | AZ4: ÇED kararı türü | BA4: ÇED görüş / karar tarihi | BB4: ÇED karar sayısı | BC4: ÇED kapsamı (Ek-1 / Ek-2) | BD4: ÇED taahhüt uygunluğu | BE4: ÇED kapsamında değişiklik | BF4: Kapasite artışı / proses planı | BG4: Çevre izin görüşü | BH4: Çevre izin görüş tarihi | BI4: İzin yönetmeliği kapsamı | BJ4: Çevre izin/lisans belgesi | BK4: Çevre izin belge no | BL4: Çevre izin kapsamı | BM4: Çevre izin bitiş | BN4: İzin yenileme takibi | BO4: İzin yenileme başvuru tarihi | BP4: Geçici faaliyet belgesi | BQ4: GFB sayı | BR4: GFB bitiş | BS4: Bekleyen kurum görüşü | BT4: Hava | BU4: Emisyon bacası | BV4: Ölçüme tabi baca sayısı | BW4: Son emisyon ölçümü | BX4: Sonraki emisyon ölçümü (elle) | BY4: Emisyon raporu uygun mu | BZ4: Baca listesi güncel mi | CA4: Baca / proses değişikliği | CB4: Sürekli emisyon sistemi | CC4: Baca ölçüm notu | CD4: Emisyon uygunsuzluğu | CE4: Su | CF4: Atıksu oluşuyor mu | CG4: Deşarj noktası / alıcı ortam | CH4: Deşarj noktası sayısı | CI4: Kanal bağlantı belgesi | CJ4: Kanal bağlantı belge no | CK4: Kanal belgesi bitiş | CL4: Deşarj / kalite kontrol izni | CM4: Deşarj izni bitiş | CN4: Atıksu arıtma tesisi | CO4: AAT kimlik belgesi | CP4: Son atıksu analiz | CQ4: Sonraki atıksu analiz | CR4: Arıtma çamuru yönetimi | CS4: Yağmur suyu / atıksu hattı | CT4: Atık | CU4: Sıfır Atık belgesi | CV4: Sıfır Atık belge no | CW4: Sıfır Atık belge tarihi | CX4: Sıfır Atık geçerlilik | CY4: Atık alanı | CZ4: Tehlikeli atık geçici depolama | DA4: Atık alanı uygun mu | DB4: Atık alanı zemin sızdırmazlığı | DC4: Atık alanı levha / etiket | DD4: Sıfır atık kutuları | DE4: Kutu etiketleri uygun mu | DF4: Atık yönetim planı | DG4: Atık yönetim planı güncel mi | DH4: Atık planı onay tarihi | DI4: Atık sözleşmeleri güncel mi | DJ4: Taşıma / bertaraf sözleşmeleri ayrı kontrol | DK4: MOTAT / atık sevki | DL4: Son MOTAT sevkiyat | DM4: Yıllık atık beyanı (TABS) | DN4: Son atık beyan yılı | DO4: TABS kontrol tarihi | DP4: Diğer | DQ4: Kirlenmiş sahalar kaydı | DR4: Kirlenmiş sahalar bildirimi | DS4: Kirlenmiş sahalar son bildirim | DT4: Kimyasal depolama | DU4: Dökülme müdahale ekipmanı | DV4: Gürültü değerlendirmesi | DW4: Gürültü ölçüm raporu | DX4: GEKAP yükümlülüğü | DY4: Son GEKAP dönemi | DZ4: Diğer beyan / bildirim | EA4: BEKRA kapsamı | EB4: BEKRA kuruluş seviyesi | EC4: BEKRA bildirimi | ED4: Son BEKRA bildirimi | EE4: BEKRA bildirimi güncel mi | EF4: BEKRA notu | EG4: Denetim | EH4: Son saha ziyareti | EI4: Sonraki saha ziyareti | EJ4: Saha ziyaret tutanağı | EK4: Son iç tetkik | EL4: Sonraki iç tetkik (elle) | EM4: İç tetkik uygunsuzluğu | EN4: Son çevre eğitimi | EO4: Sonraki çevre eğitimi (elle) | EP4: Eğitim katılım tutanağı | EQ4: Açık uygunsuzluk / eksik evrak | ER4: Açık uygunsuzluk sayısı | ES4: Uygunsuzluk kapanış hedefi | ET4: Firmadan beklenen | EU4: Danışmanın yapacağı iş | EV4: Son il müdürlüğü denetimi | EW4: Denetim sonrası eksikler | EX4: İdari yaptırım / ceza | EY4: Çevresel şikâyet | EZ4: Resmî yazışma konusu | FA4: Resmî yazı cevap son tarihi | FB4: Öncelikli işlem son tarihi | FC4: Takvim | FD4: İç tetkik sonraki (+1 yıl) | FE4: İç tetkik uyarı başlangıcı | FF4: Eğitim sonraki (+1 yıl) | FG4: Eğitim uyarı başlangıcı | FH4: Sıfır Atık bitiş (+5 yıl) | FI4: Sıfır Atık başvuru (3 ay önce) | FJ4: Atık planı bitiş (+3 yıl) | FK4: Atık planı başvuru (3 ay önce) | FL4: Emisyon teyidi (+2 yıl) | FM4: Emisyon başvuru (45 gün önce) | FN4: İzin başvuru son (180 gün önce) | FO4: Çevre izni bitiş | FP4: Çevre izni başvurusu | FQ4: GFB bitiş | FR4: Sözleşme bitiş | FS4: Sıfır Atık bitiş | FT4: Atık planı bitiş | FU4: Emisyon teyidi | FV4: Emisyon ölçümü | FW4: İç tetkik | FX4: İç tetkik planı | FY4: Çevre eğitimi | FZ4: Eğitim planı | GA4: Kanal belgesi bitiş | GB4: Deşarj izni bitiş | GC4: Atıksu analizi | GD4: Saha ziyareti | GE4: Resmî yazı cevabı | GF4: Uygunsuzluk kapanışı | GG4: Öncelikli işlem
A5: 1 | C5: =IF(B5="","",((P5="Süresi geçti")+(P5="Yaklaşıyor")+(P5="Tarih hatalı"))+((Q5="Süresi geçti")+(Q5="Yaklaşıyor")+(Q5="Tarih hatalı"))+((R5="Süresi geçti")+(R5="Yaklaşıyor")+(R5="Tarih hatalı"))+((S5="Süresi geçti")+(S5="Yaklaşıyor")+(S5="Tarih hatalı"))+((T5="Süresi geçti")+(T5="Yaklaşıyor")+(T5="Tarih hatalı"))+((U5="Süresi geçti")+(U5="Yaklaşıyor")+(U5="Tarih hatalı"))+((V5="Süresi geçti")+(V5="Yaklaşıyor")+(V5="Tarih hatalı"))) | D5: =IF(OR(B5="",E5=""),"",INDEX($FO$4:$GG$4,1,MATCH(E5,FO5:GG5,0))) | E5: =IF(B5="","",IF(COUNT(FO5:GG5)=0,"",SMALL(FO5:GG5,1))) | F5: =IF(E5="","",E5-TODAY()) | P5: =IF(B5="","",IF(NOT(ISNUMBER(AL5)),"Tarih girilmedi",IFERROR(IF(TODAY()>AL5,"Süresi geçti",IF(TODAY()>=(AL5-60),"Yaklaşıyor","Takipte")),"Tarih hatalı"))) | Q5: =IF(B5="","",IF(NOT(ISNUMBER(EK5)),"Tarih girilmedi",IFERROR(IF(TODAY()>EDATE(EK5,12),"Süresi geçti",IF(TODAY()>=EDATE(EK5,11),"Yaklaşıyor","Takipte")),"Tarih hatalı"))) | R5: =IF(B5="","",IF(NOT(ISNUMBER(EN5)),"Tarih girilmedi",IFERROR(IF(TODAY()>EDATE(EN5,12),"Süresi geçti",IF(TODAY()>=EDATE(EN5,11),"Yaklaşıyor","Takipte")),"Tarih hatalı"))) | S5: =IF(B5="","",IF(NOT(ISNUMBER(CW5)),"Tarih girilmedi",IFERROR(IF(TODAY()>EDATE(CW5,60),"Süresi geçti",IF(TODAY()>=EDATE(CW5,57),"Yaklaşıyor","Takipte")),"Tarih hatalı"))) | T5: =IF(B5="","",IF(NOT(ISNUMBER(DH5)),"Tarih girilmedi",IFERROR(IF(TODAY()>EDATE(DH5,36),"Süresi geçti",IF(TODAY()>=EDATE(DH5,33),"Yaklaşıyor","Takipte")),"Tarih hatalı"))) | U5: =IF(B5="","",IF(NOT(ISNUMBER(BW5)),"Tarih girilmedi",IFERROR(IF(TODAY()>EDATE(BW5,24),"Süresi geçti",IF(TODAY()>=(EDATE(BW5,24)-45),"Yaklaşıyor","Takipte")),"Tarih hatalı"))) | V5: =IF(B5="","",IF(NOT(ISNUMBER(BM5)),"Tarih girilmedi",IFERROR(IF(TODAY()>BM5,"Süresi geçti",IF(TODAY()>=(BM5-180),"Yaklaşıyor","Takipte")),"Tarih hatalı"))) | FD5: =IF(B5="","",IF(NOT(ISNUMBER(EK5)),"Tarih girilmedi",IFERROR(EDATE(EK5,12),"Tarih hatalı"))) | FE5: =IF(B5="","",IF(NOT(ISNUMBER(EK5)),"Tarih girilmedi",IFERROR(EDATE(EK5,11),"Tarih hatalı"))) | FF5: =IF(B5="","",IF(NOT(ISNUMBER(EN5)),"Tarih girilmedi",IFERROR(EDATE(EN5,12),"Tarih hatalı"))) | FG5: =IF(B5="","",IF(NOT(ISNUMBER(EN5)),"Tarih girilmedi",IFERROR(EDATE(EN5,11),"Tarih hatalı"))) | FH5: =IF(B5="","",IF(NOT(ISNUMBER(CW5)),"Tarih girilmedi",IFERROR(EDATE(CW5,60),"Tarih hatalı"))) | FI5: =IF(B5="","",IF(NOT(ISNUMBER(CW5)),"Tarih girilmedi",IFERROR(EDATE(CW5,57),"Tarih hatalı"))) | FJ5: =IF(B5="","",IF(NOT(ISNUMBER(DH5)),"Tarih girilmedi",IFERROR(EDATE(DH5,36),"Tarih hatalı"))) | FK5: =IF(B5="","",IF(NOT(ISNUMBER(DH5)),"Tarih girilmedi",IFERROR(EDATE(DH5,33),"Tarih hatalı"))) | FL5: =IF(B5="","",IF(NOT(ISNUMBER(BW5)),"Tarih girilmedi",IFERROR(EDATE(BW5,24),"Tarih hatalı"))) | FM5: =IF(B5="","",IF(NOT(ISNUMBER(BW5)),"Tarih girilmedi",IFERROR(EDATE(BW5,24)-45,"Tarih hatalı"))) | FN5: =IF(B5="","",IF(NOT(ISNUMBER(BM5)),"Tarih girilmedi",IFERROR(BM5-180,"Tarih hatalı"))) | FO5: =IF(OR(B5="",NOT(ISNUMBER(BM5))),"",BM5) | FP5: =IF(OR(B5="",NOT(ISNUMBER(BM5))),"",BM5-180) | FQ5: =IF(OR(B5="",NOT(ISNUMBER(BR5))),"",BR5) | FR5: =IF(OR(B5="",NOT(ISNUMBER(AL5))),"",AL5) | FS5: =IF(OR(B5="",NOT(ISNUMBER(CW5))),"",EDATE(CW5,60)) | FT5: =IF(OR(B5="",NOT(ISNUMBER(DH5))),"",EDATE(DH5,36)) | FU5: =IF(OR(B5="",NOT(ISNUMBER(BW5))),"",EDATE(BW5,24)) | FV5: =IF(OR(B5="",NOT(ISNUMBER(BX5))),"",BX5) | FW5: =IF(OR(B5="",NOT(ISNUMBER(EK5))),"",EDATE(EK5,12)) | FX5: =IF(OR(B5="",NOT(ISNUMBER(EL5))),"",EL5) | FY5: =IF(OR(B5="",NOT(ISNUMBER(EN5))),"",EDATE(EN5,12)) | FZ5: =IF(OR(B5="",NOT(ISNUMBER(EO5))),"",EO5) | GA5: =IF(OR(B5="",NOT(ISNUMBER(CK5))),"",CK5) | GB5: =IF(OR(B5="",NOT(ISNUMBER(CM5))),"",CM5) | GC5: =IF(OR(B5="",NOT(ISNUMBER(CQ5))),"",CQ5) | GD5: =IF(OR(B5="",NOT(ISNUMBER(EI5))),"",EI5) | GE5: =IF(OR(B5="",NOT(ISNUMBER(FA5))),"",FA5) | GF5: =IF(OR(B5="",NOT(ISNUMBER(ES5))),"",ES5) | GG5: =IF(OR(B5="",NOT(ISNUMBER(FB5))),"",FB5)
A6: 2 | C6: =IF(B6="","",((P6="Süresi geçti")+(P6="Yaklaşıyor")+(P6="Tarih hatalı"))+((Q6="Süresi geçti")+(Q6="Yaklaşıyor")+(Q6="Tarih hatalı"))+((R6="Süresi geçti")+(R6="Yaklaşıyor")+(R6="Tarih hatalı"))+((S6="Süresi geçti")+(S6="Yaklaşıyor")+(S6="Tarih hatalı"))+((T6="Süresi geçti")+(T6="Yaklaşıyor")+(T6="Tarih hatalı"))+((U6="Süresi geçti")+(U6="Yaklaşıyor")+(U6="Tarih hatalı"))+((V6="Süresi geçti")+(V6="Yaklaşıyor")+(V6="Tarih hatalı"))) | D6: =IF(OR(B6="",E6=""),"",INDEX($FO$4:$GG$4,1,MATCH(E6,FO6:GG6,0))) | E6: =IF(B6="","",IF(COUNT(FO6:GG6)=0,"",SMALL(FO6:GG6,1))) | F6: =IF(E6="","",E6-TODAY()) | P6: =IF(B6="","",IF(NOT(ISNUMBER(AL6)),"Tarih girilmedi",IFERROR(IF(TODAY()>AL6,"Süresi geçti",IF(TODAY()>=(AL6-60),"Yaklaşıyor","Takipte")),"Tarih hatalı"))) | Q6: =IF(B6="","",IF(NOT(ISNUMBER(EK6)),"Tarih girilmedi",IFERROR(IF(TODAY()>EDATE(EK6,12),"Süresi geçti",IF(TODAY()>=EDATE(EK6,11),"Yaklaşıyor","Takipte")),"Tarih hatalı"))) | R6: =IF(B6="","",IF(NOT(ISNUMBER(EN6)),"Tarih girilmedi",IFERROR(IF(TODAY()>EDATE(EN6,12),"Süresi geçti",IF(TODAY()>=EDATE(EN6,11),"Yaklaşıyor","Takipte")),"Tarih hatalı"))) | S6: =IF(B6="","",IF(NOT(ISNUMBER(CW6)),"Tarih girilmedi",IFERROR(IF(TODAY()>EDATE(CW6,60),"Süresi geçti",IF(TODAY()>=EDATE(CW6,57),"Yaklaşıyor","Takipte")),"Tarih hatalı"))) | T6: =IF(B6="","",IF(NOT(ISNUMBER(DH6)),"Tarih girilmedi",IFERROR(IF(TODAY()>EDATE(DH6,36),"Süresi geçti",IF(TODAY()>=EDATE(DH6,33),"Yaklaşıyor","Takipte")),"Tarih hatalı"))) | U6: =IF(B6="","",IF(NOT(ISNUMBER(BW6)),"Tarih girilmedi",IFERROR(IF(TODAY()>EDATE(BW6,24),"Süresi geçti",IF(TODAY()>=(EDATE(BW6,24)-45),"Yaklaşıyor","Takipte")),"Tarih hatalı"))) | V6: =IF(B6="","",IF(NOT(ISNUMBER(BM6)),"Tarih girilmedi",IFERROR(IF(TODAY()>BM6,"Süresi geçti",IF(TODAY()>=(BM6-180),"Yaklaşıyor","Takipte")),"Tarih hatalı"))) | FD6: =IF(B6="","",IF(NOT(ISNUMBER(EK6)),"Tarih girilmedi",IFERROR(EDATE(EK6,12),"Tarih hatalı"))) | FE6: =IF(B6="","",IF(NOT(ISNUMBER(EK6)),"Tarih girilmedi",IFERROR(EDATE(EK6,11),"Tarih hatalı"))) | FF6: =IF(B6="","",IF(NOT(ISNUMBER(EN6)),"Tarih girilmedi",IFERROR(EDATE(EN6,12),"Tarih hatalı"))) | FG6: =IF(B6="","",IF(NOT(ISNUMBER(EN6)),"Tarih girilmedi",IFERROR(EDATE(EN6,11),"Tarih hatalı"))) | FH6: =IF(B6="","",IF(NOT(ISNUMBER(CW6)),"Tarih girilmedi",IFERROR(EDATE(CW6,60),"Tarih hatalı"))) | FI6: =IF(B6="","",IF(NOT(ISNUMBER(CW6)),"Tarih girilmedi",IFERROR(EDATE(CW6,57),"Tarih hatalı"))) | FJ6: =IF(B6="","",IF(NOT(ISNUMBER(DH6)),"Tarih girilmedi",IFERROR(EDATE(DH6,36),"Tarih hatalı"))) | FK6: =IF(B6="","",IF(NOT(ISNUMBER(DH6)),"Tarih girilmedi",IFERROR(EDATE(DH6,33),"Tarih hatalı"))) | FL6: =IF(B6="","",IF(NOT(ISNUMBER(BW6)),"Tarih girilmedi",IFERROR(EDATE(BW6,24),"Tarih hatalı"))) | FM6: =IF(B6="","",IF(NOT(ISNUMBER(BW6)),"Tarih girilmedi",IFERROR(EDATE(BW6,24)-45,"Tarih hatalı"))) | FN6: =IF(B6="","",IF(NOT(ISNUMBER(BM6)),"Tarih girilmedi",IFERROR(BM6-180,"Tarih hatalı"))) | FO6: =IF(OR(B6="",NOT(ISNUMBER(BM6))),"",BM6) | FP6: =IF(OR(B6="",NOT(ISNUMBER(BM6))),"",BM6-180) | FQ6: =IF(OR(B6="",NOT(ISNUMBER(BR6))),"",BR6) | FR6: =IF(OR(B6="",NOT(ISNUMBER(AL6))),"",AL6) | FS6: =IF(OR(B6="",NOT(ISNUMBER(CW6))),"",EDATE(CW6,60)) | FT6: =IF(OR(B6="",NOT(ISNUMBER(DH6))),"",EDATE(DH6,36)) | FU6: =IF(OR(B6="",NOT(ISNUMBER(BW6))),"",EDATE(BW6,24)) | FV6: =IF(OR(B6="",NOT(ISNUMBER(BX6))),"",BX6) | FW6: =IF(OR(B6="",NOT(ISNUMBER(EK6))),"",EDATE(EK6,12)) | FX6: =IF(OR(B6="",NOT(ISNUMBER(EL6))),"",EL6) | FY6: =IF(OR(B6="",NOT(ISNUMBER(EN6))),"",EDATE(EN6,12)) | FZ6: =IF(OR(B6="",NOT(ISNUMBER(EO6))),"",EO6) | GA6: =IF(OR(B6="",NOT(ISNUMBER(CK6))),"",CK6) | GB6: =IF(OR(B6="",NOT(ISNUMBER(CM6))),"",CM6) | GC6: =IF(OR(B6="",NOT(ISNUMBER(CQ6))),"",CQ6) | GD6: =IF(OR(B6="",NOT(ISNUMBER(EI6))),"",EI6) | GE6: =IF(OR(B6="",NOT(ISNUMBER(FA6))),"",FA6) | GF6: =IF(OR(B6="",NOT(ISNUMBER(ES6))),"",ES6) | GG6: =IF(OR(B6="",NOT(ISNUMBER(FB6))),"",FB6)
A7: 3 | C7: =IF(B7="","",((P7="Süresi geçti")+(P7="Yaklaşıyor")+(P7="Tarih hatalı"))+((Q7="Süresi geçti")+(Q7="Yaklaşıyor")+(Q7="Tarih hatalı"))+((R7="Süresi geçti")+(R7="Yaklaşıyor")+(R7="Tarih hatalı"))+((S7="Süresi geçti")+(S7="Yaklaşıyor")+(S7="Tarih hatalı"))+((T7="Süresi geçti")+(T7="Yaklaşıyor")+(T7="Tarih hatalı"))+((U7="Süresi geçti")+(U7="Yaklaşıyor")+(U7="Tarih hatalı"))+((V7="Süresi geçti")+(V7="Yaklaşıyor")+(V7="Tarih hatalı"))) | D7: =IF(OR(B7="",E7=""),"",INDEX($FO$4:$GG$4,1,MATCH(E7,FO7:GG7,0))) | E7: =IF(B7="","",IF(COUNT(FO7:GG7)=0,"",SMALL(FO7:GG7,1))) | F7: =IF(E7="","",E7-TODAY()) | P7: =IF(B7="","",IF(NOT(ISNUMBER(AL7)),"Tarih girilmedi",IFERROR(IF(TODAY()>AL7,"Süresi geçti",IF(TODAY()>=(AL7-60),"Yaklaşıyor","Takipte")),"Tarih hatalı"))) | Q7: =IF(B7="","",IF(NOT(ISNUMBER(EK7)),"Tarih girilmedi",IFERROR(IF(TODAY()>EDATE(EK7,12),"Süresi geçti",IF(TODAY()>=EDATE(EK7,11),"Yaklaşıyor","Takipte")),"Tarih hatalı"))) | R7: =IF(B7="","",IF(NOT(ISNUMBER(EN7)),"Tarih girilmedi",IFERROR(IF(TODAY()>EDATE(EN7,12),"Süresi geçti",IF(TODAY()>=EDATE(EN7,11),"Yaklaşıyor","Takipte")),"Tarih hatalı"))) | S7: =IF(B7="","",IF(NOT(ISNUMBER(CW7)),"Tarih girilmedi",IFERROR(IF(TODAY()>EDATE(CW7,60),"Süresi geçti",IF(TODAY()>=EDATE(CW7,57),"Yaklaşıyor","Takipte")),"Tarih hatalı"))) | T7: =IF(B7="","",IF(NOT(ISNUMBER(DH7)),"Tarih girilmedi",IFERROR(IF(TODAY()>EDATE(DH7,36),"Süresi geçti",IF(TODAY()>=EDATE(DH7,33),"Yaklaşıyor","Takipte")),"Tarih hatalı"))) | U7: =IF(B7="","",IF(NOT(ISNUMBER(BW7)),"Tarih girilmedi",IFERROR(IF(TODAY()>EDATE(BW7,24),"Süresi geçti",IF(TODAY()>=(EDATE(BW7,24)-45),"Yaklaşıyor","Takipte")),"Tarih hatalı"))) | V7: =IF(B7="","",IF(NOT(ISNUMBER(BM7)),"Tarih girilmedi",IFERROR(IF(TODAY()>BM7,"Süresi geçti",IF(TODAY()>=(BM7-180),"Yaklaşıyor","Takipte")),"Tarih hatalı"))) | FD7: =IF(B7="","",IF(NOT(ISNUMBER(EK7)),"Tarih girilmedi",IFERROR(EDATE(EK7,12),"Tarih hatalı"))) | FE7: =IF(B7="","",IF(NOT(ISNUMBER(EK7)),"Tarih girilmedi",IFERROR(EDATE(EK7,11),"Tarih hatalı"))) | FF7: =IF(B7="","",IF(NOT(ISNUMBER(EN7)),"Tarih girilmedi",IFERROR(EDATE(EN7,12),"Tarih hatalı"))) | FG7: =IF(B7="","",IF(NOT(ISNUMBER(EN7)),"Tarih girilmedi",IFERROR(EDATE(EN7,11),"Tarih hatalı"))) | FH7: =IF(B7="","",IF(NOT(ISNUMBER(CW7)),"Tarih girilmedi",IFERROR(EDATE(CW7,60),"Tarih hatalı"))) | FI7: =IF(B7="","",IF(NOT(ISNUMBER(CW7)),"Tarih girilmedi",IFERROR(EDATE(CW7,57),"Tarih hatalı"))) | FJ7: =IF(B7="","",IF(NOT(ISNUMBER(DH7)),"Tarih girilmedi",IFERROR(EDATE(DH7,36),"Tarih hatalı"))) | FK7: =IF(B7="","",IF(NOT(ISNUMBER(DH7)),"Tarih girilmedi",IFERROR(EDATE(DH7,33),"Tarih hatalı"))) | FL7: =IF(B7="","",IF(NOT(ISNUMBER(BW7)),"Tarih girilmedi",IFERROR(EDATE(BW7,24),"Tarih hatalı"))) | FM7: =IF(B7="","",IF(NOT(ISNUMBER(BW7)),"Tarih girilmedi",IFERROR(EDATE(BW7,24)-45,"Tarih hatalı"))) | FN7: =IF(B7="","",IF(NOT(ISNUMBER(BM7)),"Tarih girilmedi",IFERROR(BM7-180,"Tarih hatalı"))) | FO7: =IF(OR(B7="",NOT(ISNUMBER(BM7))),"",BM7) | FP7: =IF(OR(B7="",NOT(ISNUMBER(BM7))),"",BM7-180) | FQ7: =IF(OR(B7="",NOT(ISNUMBER(BR7))),"",BR7) | FR7: =IF(OR(B7="",NOT(ISNUMBER(AL7))),"",AL7) | FS7: =IF(OR(B7="",NOT(ISNUMBER(CW7))),"",EDATE(CW7,60)) | FT7: =IF(OR(B7="",NOT(ISNUMBER(DH7))),"",EDATE(DH7,36)) | FU7: =IF(OR(B7="",NOT(ISNUMBER(BW7))),"",EDATE(BW7,24)) | FV7: =IF(OR(B7="",NOT(ISNUMBER(BX7))),"",BX7) | FW7: =IF(OR(B7="",NOT(ISNUMBER(EK7))),"",EDATE(EK7,12)) | FX7: =IF(OR(B7="",NOT(ISNUMBER(EL7))),"",EL7) | FY7: =IF(OR(B7="",NOT(ISNUMBER(EN7))),"",EDATE(EN7,12)) | FZ7: =IF(OR(B7="",NOT(ISNUMBER(EO7))),"",EO7) | GA7: =IF(OR(B7="",NOT(ISNUMBER(CK7))),"",CK7) | GB7: =IF(OR(B7="",NOT(ISNUMBER(CM7))),"",CM7) | GC7: =IF(OR(B7="",NOT(ISNUMBER(CQ7))),"",CQ7) | GD7: =IF(OR(B7="",NOT(ISNUMBER(EI7))),"",EI7) | GE7: =IF(OR(B7="",NOT(ISNUMBER(FA7))),"",FA7) | GF7: =IF(OR(B7="",NOT(ISNUMBER(ES7))),"",ES7) | GG7: =IF(OR(B7="",NOT(ISNUMBER(FB7))),"",FB7)
A8: 4 | C8: =IF(B8="","",((P8="Süresi geçti")+(P8="Yaklaşıyor")+(P8="Tarih hatalı"))+((Q8="Süresi geçti")+(Q8="Yaklaşıyor")+(Q8="Tarih hatalı"))+((R8="Süresi geçti")+(R8="Yaklaşıyor")+(R8="Tarih hatalı"))+((S8="Süresi geçti")+(S8="Yaklaşıyor")+(S8="Tarih hatalı"))+((T8="Süresi geçti")+(T8="Yaklaşıyor")+(T8="Tarih hatalı"))+((U8="Süresi geçti")+(U8="Yaklaşıyor")+(U8="Tarih hatalı"))+((V8="Süresi geçti")+(V8="Yaklaşıyor")+(V8="Tarih hatalı"))) | D8: =IF(OR(B8="",E8=""),"",INDEX($FO$4:$GG$4,1,MATCH(E8,FO8:GG8,0))) | E8: =IF(B8="","",IF(COUNT(FO8:GG8)=0,"",SMALL(FO8:GG8,1))) | F8: =IF(E8="","",E8-TODAY()) | P8: =IF(B8="","",IF(NOT(ISNUMBER(AL8)),"Tarih girilmedi",IFERROR(IF(TODAY()>AL8,"Süresi geçti",IF(TODAY()>=(AL8-60),"Yaklaşıyor","Takipte")),"Tarih hatalı"))) | Q8: =IF(B8="","",IF(NOT(ISNUMBER(EK8)),"Tarih girilmedi",IFERROR(IF(TODAY()>EDATE(EK8,12),"Süresi geçti",IF(TODAY()>=EDATE(EK8,11),"Yaklaşıyor","Takipte")),"Tarih hatalı"))) | R8: =IF(B8="","",IF(NOT(ISNUMBER(EN8)),"Tarih girilmedi",IFERROR(IF(TODAY()>EDATE(EN8,12),"Süresi geçti",IF(TODAY()>=EDATE(EN8,11),"Yaklaşıyor","Takipte")),"Tarih hatalı"))) | S8: =IF(B8="","",IF(NOT(ISNUMBER(CW8)),"Tarih girilmedi",IFERROR(IF(TODAY()>EDATE(CW8,60),"Süresi geçti",IF(TODAY()>=EDATE(CW8,57),"Yaklaşıyor","Takipte")),"Tarih hatalı"))) | T8: =IF(B8="","",IF(NOT(ISNUMBER(DH8)),"Tarih girilmedi",IFERROR(IF(TODAY()>EDATE(DH8,36),"Süresi geçti",IF(TODAY()>=EDATE(DH8,33),"Yaklaşıyor","Takipte")),"Tarih hatalı"))) | U8: =IF(B8="","",IF(NOT(ISNUMBER(BW8)),"Tarih girilmedi",IFERROR(IF(TODAY()>EDATE(BW8,24),"Süresi geçti",IF(TODAY()>=(EDATE(BW8,24)-45),"Yaklaşıyor","Takipte")),"Tarih hatalı"))) | V8: =IF(B8="","",IF(NOT(ISNUMBER(BM8)),"Tarih girilmedi",IFERROR(IF(TODAY()>BM8,"Süresi geçti",IF(TODAY()>=(BM8-180),"Yaklaşıyor","Takipte")),"Tarih hatalı"))) | FD8: =IF(B8="","",IF(NOT(ISNUMBER(EK8)),"Tarih girilmedi",IFERROR(EDATE(EK8,12),"Tarih hatalı"))) | FE8: =IF(B8="","",IF(NOT(ISNUMBER(EK8)),"Tarih girilmedi",IFERROR(EDATE(EK8,11),"Tarih hatalı"))) | FF8: =IF(B8="","",IF(NOT(ISNUMBER(EN8)),"Tarih girilmedi",IFERROR(EDATE(EN8,12),"Tarih hatalı"))) | FG8: =IF(B8="","",IF(NOT(ISNUMBER(EN8)),"Tarih girilmedi",IFERROR(EDATE(EN8,11),"Tarih hatalı"))) | FH8: =IF(B8="","",IF(NOT(ISNUMBER(CW8)),"Tarih girilmedi",IFERROR(EDATE(CW8,60),"Tarih hatalı"))) | FI8: =IF(B8="","",IF(NOT(ISNUMBER(CW8)),"Tarih girilmedi",IFERROR(EDATE(CW8,57),"Tarih hatalı"))) | FJ8: =IF(B8="","",IF(NOT(ISNUMBER(DH8)),"Tarih girilmedi",IFERROR(EDATE(DH8,36),"Tarih hatalı"))) | FK8: =IF(B8="","",IF(NOT(ISNUMBER(DH8)),"Tarih girilmedi",IFERROR(EDATE(DH8,33),"Tarih hatalı"))) | FL8: =IF(B8="","",IF(NOT(ISNUMBER(BW8)),"Tarih girilmedi",IFERROR(EDATE(BW8,24),"Tarih hatalı"))) | FM8: =IF(B8="","",IF(NOT(ISNUMBER(BW8)),"Tarih girilmedi",IFERROR(EDATE(BW8,24)-45,"Tarih hatalı"))) | FN8: =IF(B8="","",IF(NOT(ISNUMBER(BM8)),"Tarih girilmedi",IFERROR(BM8-180,"Tarih hatalı"))) | FO8: =IF(OR(B8="",NOT(ISNUMBER(BM8))),"",BM8) | FP8: =IF(OR(B8="",NOT(ISNUMBER(BM8))),"",BM8-180) | FQ8: =IF(OR(B8="",NOT(ISNUMBER(BR8))),"",BR8) | FR8: =IF(OR(B8="",NOT(ISNUMBER(AL8))),"",AL8) | FS8: =IF(OR(B8="",NOT(ISNUMBER(CW8))),"",EDATE(CW8,60)) | FT8: =IF(OR(B8="",NOT(ISNUMBER(DH8))),"",EDATE(DH8,36)) | FU8: =IF(OR(B8="",NOT(ISNUMBER(BW8))),"",EDATE(BW8,24)) | FV8: =IF(OR(B8="",NOT(ISNUMBER(BX8))),"",BX8) | FW8: =IF(OR(B8="",NOT(ISNUMBER(EK8))),"",EDATE(EK8,12)) | FX8: =IF(OR(B8="",NOT(ISNUMBER(EL8))),"",EL8) | FY8: =IF(OR(B8="",NOT(ISNUMBER(EN8))),"",EDATE(EN8,12)) | FZ8: =IF(OR(B8="",NOT(ISNUMBER(EO8))),"",EO8) | GA8: =IF(OR(B8="",NOT(ISNUMBER(CK8))),"",CK8) | GB8: =IF(OR(B8="",NOT(ISNUMBER(CM8))),"",CM8) | GC8: =IF(OR(B8="",NOT(ISNUMBER(CQ8))),"",CQ8) | GD8: =IF(OR(B8="",NOT(ISNUMBER(EI8))),"",EI8) | GE8: =IF(OR(B8="",NOT(ISNUMBER(FA8))),"",FA8) | GF8: =IF(OR(B8="",NOT(ISNUMBER(ES8))),"",ES8) | GG8: =IF(OR(B8="",NOT(ISNUMBER(FB8))),"",FB8)
A9: 5 | C9: =IF(B9="","",((P9="Süresi geçti")+(P9="Yaklaşıyor")+(P9="Tarih hatalı"))+((Q9="Süresi geçti")+(Q9="Yaklaşıyor")+(Q9="Tarih hatalı"))+((R9="Süresi geçti")+(R9="Yaklaşıyor")+(R9="Tarih hatalı"))+((S9="Süresi geçti")+(S9="Yaklaşıyor")+(S9="Tarih hatalı"))+((T9="Süresi geçti")+(T9="Yaklaşıyor")+(T9="Tarih hatalı"))+((U9="Süresi geçti")+(U9="Yaklaşıyor")+(U9="Tarih hatalı"))+((V9="Süresi geçti")+(V9="Yaklaşıyor")+(V9="Tarih hatalı"))) | D9: =IF(OR(B9="",E9=""),"",INDEX($FO$4:$GG$4,1,MATCH(E9,FO9:GG9,0))) | E9: =IF(B9="","",IF(COUNT(FO9:GG9)=0,"",SMALL(FO9:GG9,1))) | F9: =IF(E9="","",E9-TODAY()) | P9: =IF(B9="","",IF(NOT(ISNUMBER(AL9)),"Tarih girilmedi",IFERROR(IF(TODAY()>AL9,"Süresi geçti",IF(TODAY()>=(AL9-60),"Yaklaşıyor","Takipte")),"Tarih hatalı"))) | Q9: =IF(B9="","",IF(NOT(ISNUMBER(EK9)),"Tarih girilmedi",IFERROR(IF(TODAY()>EDATE(EK9,12),"Süresi geçti",IF(TODAY()>=EDATE(EK9,11),"Yaklaşıyor","Takipte")),"Tarih hatalı"))) | R9: =IF(B9="","",IF(NOT(ISNUMBER(EN9)),"Tarih girilmedi",IFERROR(IF(TODAY()>EDATE(EN9,12),"Süresi geçti",IF(TODAY()>=EDATE(EN9,11),"Yaklaşıyor","Takipte")),"Tarih hatalı"))) | S9: =IF(B9="","",IF(NOT(ISNUMBER(CW9)),"Tarih girilmedi",IFERROR(IF(TODAY()>EDATE(CW9,60),"Süresi geçti",IF(TODAY()>=EDATE(CW9,57),"Yaklaşıyor","Takipte")),"Tarih hatalı"))) | T9: =IF(B9="","",IF(NOT(ISNUMBER(DH9)),"Tarih girilmedi",IFERROR(IF(TODAY()>EDATE(DH9,36),"Süresi geçti",IF(TODAY()>=EDATE(DH9,33),"Yaklaşıyor","Takipte")),"Tarih hatalı"))) | U9: =IF(B9="","",IF(NOT(ISNUMBER(BW9)),"Tarih girilmedi",IFERROR(IF(TODAY()>EDATE(BW9,24),"Süresi geçti",IF(TODAY()>=(EDATE(BW9,24)-45),"Yaklaşıyor","Takipte")),"Tarih hatalı"))) | V9: =IF(B9="","",IF(NOT(ISNUMBER(BM9)),"Tarih girilmedi",IFERROR(IF(TODAY()>BM9,"Süresi geçti",IF(TODAY()>=(BM9-180),"Yaklaşıyor","Takipte")),"Tarih hatalı"))) | FD9: =IF(B9="","",IF(NOT(ISNUMBER(EK9)),"Tarih girilmedi",IFERROR(EDATE(EK9,12),"Tarih hatalı"))) | FE9: =IF(B9="","",IF(NOT(ISNUMBER(EK9)),"Tarih girilmedi",IFERROR(EDATE(EK9,11),"Tarih hatalı"))) | FF9: =IF(B9="","",IF(NOT(ISNUMBER(EN9)),"Tarih girilmedi",IFERROR(EDATE(EN9,12),"Tarih hatalı"))) | FG9: =IF(B9="","",IF(NOT(ISNUMBER(EN9)),"Tarih girilmedi",IFERROR(EDATE(EN9,11),"Tarih hatalı"))) | FH9: =IF(B9="","",IF(NOT(ISNUMBER(CW9)),"Tarih girilmedi",IFERROR(EDATE(CW9,60),"Tarih hatalı"))) | FI9: =IF(B9="","",IF(NOT(ISNUMBER(CW9)),"Tarih girilmedi",IFERROR(EDATE(CW9,57),"Tarih hatalı"))) | FJ9: =IF(B9="","",IF(NOT(ISNUMBER(DH9)),"Tarih girilmedi",IFERROR(EDATE(DH9,36),"Tarih hatalı"))) | FK9: =IF(B9="","",IF(NOT(ISNUMBER(DH9)),"Tarih girilmedi",IFERROR(EDATE(DH9,33),"Tarih hatalı"))) | FL9: =IF(B9="","",IF(NOT(ISNUMBER(BW9)),"Tarih girilmedi",IFERROR(EDATE(BW9,24),"Tarih hatalı"))) | FM9: =IF(B9="","",IF(NOT(ISNUMBER(BW9)),"Tarih girilmedi",IFERROR(EDATE(BW9,24)-45,"Tarih hatalı"))) | FN9: =IF(B9="","",IF(NOT(ISNUMBER(BM9)),"Tarih girilmedi",IFERROR(BM9-180,"Tarih hatalı"))) | FO9: =IF(OR(B9="",NOT(ISNUMBER(BM9))),"",BM9) | FP9: =IF(OR(B9="",NOT(ISNUMBER(BM9))),"",BM9-180) | FQ9: =IF(OR(B9="",NOT(ISNUMBER(BR9))),"",BR9) | FR9: =IF(OR(B9="",NOT(ISNUMBER(AL9))),"",AL9) | FS9: =IF(OR(B9="",NOT(ISNUMBER(CW9))),"",EDATE(CW9,60)) | FT9: =IF(OR(B9="",NOT(ISNUMBER(DH9))),"",EDATE(DH9,36)) | FU9: =IF(OR(B9="",NOT(ISNUMBER(BW9))),"",EDATE(BW9,24)) | FV9: =IF(OR(B9="",NOT(ISNUMBER(BX9))),"",BX9) | FW9: =IF(OR(B9="",NOT(ISNUMBER(EK9))),"",EDATE(EK9,12)) | FX9: =IF(OR(B9="",NOT(ISNUMBER(EL9))),"",EL9) | FY9: =IF(OR(B9="",NOT(ISNUMBER(EN9))),"",EDATE(EN9,12)) | FZ9: =IF(OR(B9="",NOT(ISNUMBER(EO9))),"",EO9) | GA9: =IF(OR(B9="",NOT(ISNUMBER(CK9))),"",CK9) | GB9: =IF(OR(B9="",NOT(ISNUMBER(CM9))),"",CM9) | GC9: =IF(OR(B9="",NOT(ISNUMBER(CQ9))),"",CQ9) | GD9: =IF(OR(B9="",NOT(ISNUMBER(EI9))),"",EI9) | GE9: =IF(OR(B9="",NOT(ISNUMBER(FA9))),"",FA9) | GF9: =IF(OR(B9="",NOT(ISNUMBER(ES9))),"",ES9) | GG9: =IF(OR(B9="",NOT(ISNUMBER(FB9))),"",FB9)
A10: 6 | C10: =IF(B10="","",((P10="Süresi geçti")+(P10="Yaklaşıyor")+(P10="Tarih hatalı"))+((Q10="Süresi geçti")+(Q10="Yaklaşıyor")+(Q10="Tarih hatalı"))+((R10="Süresi geçti")+(R10="Yaklaşıyor")+(R10="Tarih hatalı"))+((S10="Süresi geçti")+(S10="Yaklaşıyor")+(S10="Tarih hatalı"))+((T10="Süresi geçti")+(T10="Yaklaşıyor")+(T10="Tarih hatalı"))+((U10="Süresi geçti")+(U10="Yaklaşıyor")+(U10="Tarih hatalı"))+((V10="Süresi geçti")+(V10="Yaklaşıyor")+(V10="Tarih hatalı"))) | D10: =IF(OR(B10="",E10=""),"",INDEX($FO$4:$GG$4,1,MATCH(E10,FO10:GG10,0))) | E10: =IF(B10="","",IF(COUNT(FO10:GG10)=0,"",SMALL(FO10:GG10,1))) | F10: =IF(E10="","",E10-TODAY()) | P10: =IF(B10="","",IF(NOT(ISNUMBER(AL10)),"Tarih girilmedi",IFERROR(IF(TODAY()>AL10,"Süresi geçti",IF(TODAY()>=(AL10-60),"Yaklaşıyor","Takipte")),"Tarih hatalı"))) | Q10: =IF(B10="","",IF(NOT(ISNUMBER(EK10)),"Tarih girilmedi",IFERROR(IF(TODAY()>EDATE(EK10,12),"Süresi geçti",IF(TODAY()>=EDATE(EK10,11),"Yaklaşıyor","Takipte")),"Tarih hatalı"))) | R10: =IF(B10="","",IF(NOT(ISNUMBER(EN10)),"Tarih girilmedi",IFERROR(IF(TODAY()>EDATE(EN10,12),"Süresi geçti",IF(TODAY()>=EDATE(EN10,11),"Yaklaşıyor","Takipte")),"Tarih hatalı"))) | S10: =IF(B10="","",IF(NOT(ISNUMBER(CW10)),"Tarih girilmedi",IFERROR(IF(TODAY()>EDATE(CW10,60),"Süresi geçti",IF(TODAY()>=EDATE(CW10,57),"Yaklaşıyor","Takipte")),"Tarih hatalı"))) | T10: =IF(B10="","",IF(NOT(ISNUMBER(DH10)),"Tarih girilmedi",IFERROR(IF(TODAY()>EDATE(DH10,36),"Süresi geçti",IF(TODAY()>=EDATE(DH10,33),"Yaklaşıyor","Takipte")),"Tarih hatalı"))) | U10: =IF(B10="","",IF(NOT(ISNUMBER(BW10)),"Tarih girilmedi",IFERROR(IF(TODAY()>EDATE(BW10,24),"Süresi geçti",IF(TODAY()>=(EDATE(BW10,24)-45),"Yaklaşıyor","Takipte")),"Tarih hatalı"))) | V10: =IF(B10="","",IF(NOT(ISNUMBER(BM10)),"Tarih girilmedi",IFERROR(IF(TODAY()>BM10,"Süresi geçti",IF(TODAY()>=(BM10-180),"Yaklaşıyor","Takipte")),"Tarih hatalı"))) | FD10: =IF(B10="","",IF(NOT(ISNUMBER(EK10)),"Tarih girilmedi",IFERROR(EDATE(EK10,12),"Tarih hatalı"))) | FE10: =IF(B10="","",IF(NOT(ISNUMBER(EK10)),"Tarih girilmedi",IFERROR(EDATE(EK10,11),"Tarih hatalı"))) | FF10: =IF(B10="","",IF(NOT(ISNUMBER(EN10)),"Tarih girilmedi",IFERROR(EDATE(EN10,12),"Tarih hatalı"))) | FG10: =IF(B10="","",IF(NOT(ISNUMBER(EN10)),"Tarih girilmedi",IFERROR(EDATE(EN10,11),"Tarih hatalı"))) | FH10: =IF(B10="","",IF(NOT(ISNUMBER(CW10)),"Tarih girilmedi",IFERROR(EDATE(CW10,60),"Tarih hatalı"))) | FI10: =IF(B10="","",IF(NOT(ISNUMBER(CW10)),"Tarih girilmedi",IFERROR(EDATE(CW10,57),"Tarih hatalı"))) | FJ10: =IF(B10="","",IF(NOT(ISNUMBER(DH10)),"Tarih girilmedi",IFERROR(EDATE(DH10,36),"Tarih hatalı"))) | FK10: =IF(B10="","",IF(NOT(ISNUMBER(DH10)),"Tarih girilmedi",IFERROR(EDATE(DH10,33),"Tarih hatalı"))) | FL10: =IF(B10="","",IF(NOT(ISNUMBER(BW10)),"Tarih girilmedi",IFERROR(EDATE(BW10,24),"Tarih hatalı"))) | FM10: =IF(B10="","",IF(NOT(ISNUMBER(BW10)),"Tarih girilmedi",IFERROR(EDATE(BW10,24)-45,"Tarih hatalı"))) | FN10: =IF(B10="","",IF(NOT(ISNUMBER(BM10)),"Tarih girilmedi",IFERROR(BM10-180,"Tarih hatalı"))) | FO10: =IF(OR(B10="",NOT(ISNUMBER(BM10))),"",BM10) | FP10: =IF(OR(B10="",NOT(ISNUMBER(BM10))),"",BM10-180) | FQ10: =IF(OR(B10="",NOT(ISNUMBER(BR10))),"",BR10) | FR10: =IF(OR(B10="",NOT(ISNUMBER(AL10))),"",AL10) | FS10: =IF(OR(B10="",NOT(ISNUMBER(CW10))),"",EDATE(CW10,60)) | FT10: =IF(OR(B10="",NOT(ISNUMBER(DH10))),"",EDATE(DH10,36)) | FU10: =IF(OR(B10="",NOT(ISNUMBER(BW10))),"",EDATE(BW10,24)) | FV10: =IF(OR(B10="",NOT(ISNUMBER(BX10))),"",BX10) | FW10: =IF(OR(B10="",NOT(ISNUMBER(EK10))),"",EDATE(EK10,12)) | FX10: =IF(OR(B10="",NOT(ISNUMBER(EL10))),"",EL10) | FY10: =IF(OR(B10="",NOT(ISNUMBER(EN10))),"",EDATE(EN10,12)) | FZ10: =IF(OR(B10="",NOT(ISNUMBER(EO10))),"",EO10) | GA10: =IF(OR(B10="",NOT(ISNUMBER(CK10))),"",CK10) | GB10: =IF(OR(B10="",NOT(ISNUMBER(CM10))),"",CM10) | GC10: =IF(OR(B10="",NOT(ISNUMBER(CQ10))),"",CQ10) | GD10: =IF(OR(B10="",NOT(ISNUMBER(EI10))),"",EI10) | GE10: =IF(OR(B10="",NOT(ISNUMBER(FA10))),"",FA10) | GF10: =IF(OR(B10="",NOT(ISNUMBER(ES10))),"",ES10) | GG10: =IF(OR(B10="",NOT(ISNUMBER(FB10))),"",FB10)
A11: 7 | C11: =IF(B11="","",((P11="Süresi geçti")+(P11="Yaklaşıyor")+(P11="Tarih hatalı"))+((Q11="Süresi geçti")+(Q11="Yaklaşıyor")+(Q11="Tarih hatalı"))+((R11="Süresi geçti")+(R11="Yaklaşıyor")+(R11="Tarih hatalı"))+((S11="Süresi geçti")+(S11="Yaklaşıyor")+(S11="Tarih hatalı"))+((T11="Süresi geçti")+(T11="Yaklaşıyor")+(T11="Tarih hatalı"))+((U11="Süresi geçti")+(U11="Yaklaşıyor")+(U11="Tarih hatalı"))+((V11="Süresi geçti")+(V11="Yaklaşıyor")+(V11="Tarih hatalı"))) | D11: =IF(OR(B11="",E11=""),"",INDEX($FO$4:$GG$4,1,MATCH(E11,FO11:GG11,0))) | E11: =IF(B11="","",IF(COUNT(FO11:GG11)=0,"",SMALL(FO11:GG11,1))) | F11: =IF(E11="","",E11-TODAY()) | P11: =IF(B11="","",IF(NOT(ISNUMBER(AL11)),"Tarih girilmedi",IFERROR(IF(TODAY()>AL11,"Süresi geçti",IF(TODAY()>=(AL11-60),"Yaklaşıyor","Takipte")),"Tarih hatalı"))) | Q11: =IF(B11="","",IF(NOT(ISNUMBER(EK11)),"Tarih girilmedi",IFERROR(IF(TODAY()>EDATE(EK11,12),"Süresi geçti",IF(TODAY()>=EDATE(EK11,11),"Yaklaşıyor","Takipte")),"Tarih hatalı"))) | R11: =IF(B11="","",IF(NOT(ISNUMBER(EN11)),"Tarih girilmedi",IFERROR(IF(TODAY()>EDATE(EN11,12),"Süresi geçti",IF(TODAY()>=EDATE(EN11,11),"Yaklaşıyor","Takipte")),"Tarih hatalı"))) | S11: =IF(B11="","",IF(NOT(ISNUMBER(CW11)),"Tarih girilmedi",IFERROR(IF(TODAY()>EDATE(CW11,60),"Süresi geçti",IF(TODAY()>=EDATE(CW11,57),"Yaklaşıyor","Takipte")),"Tarih hatalı"))) | T11: =IF(B11="","",IF(NOT(ISNUMBER(DH11)),"Tarih girilmedi",IFERROR(IF(TODAY()>EDATE(DH11,36),"Süresi geçti",IF(TODAY()>=EDATE(DH11,33),"Yaklaşıyor","Takipte")),"Tarih hatalı"))) | U11: =IF(B11="","",IF(NOT(ISNUMBER(BW11)),"Tarih girilmedi",IFERROR(IF(TODAY()>EDATE(BW11,24),"Süresi geçti",IF(TODAY()>=(EDATE(BW11,24)-45),"Yaklaşıyor","Takipte")),"Tarih hatalı"))) | V11: =IF(B11="","",IF(NOT(ISNUMBER(BM11)),"Tarih girilmedi",IFERROR(IF(TODAY()>BM11,"Süresi geçti",IF(TODAY()>=(BM11-180),"Yaklaşıyor","Takipte")),"Tarih hatalı"))) | FD11: =IF(B11="","",IF(NOT(ISNUMBER(EK11)),"Tarih girilmedi",IFERROR(EDATE(EK11,12),"Tarih hatalı"))) | FE11: =IF(B11="","",IF(NOT(ISNUMBER(EK11)),"Tarih girilmedi",IFERROR(EDATE(EK11,11),"Tarih hatalı"))) | FF11: =IF(B11="","",IF(NOT(ISNUMBER(EN11)),"Tarih girilmedi",IFERROR(EDATE(EN11,12),"Tarih hatalı"))) | FG11: =IF(B11="","",IF(NOT(ISNUMBER(EN11)),"Tarih girilmedi",IFERROR(EDATE(EN11,11),"Tarih hatalı"))) | FH11: =IF(B11="","",IF(NOT(ISNUMBER(CW11)),"Tarih girilmedi",IFERROR(EDATE(CW11,60),"Tarih hatalı"))) | FI11: =IF(B11="","",IF(NOT(ISNUMBER(CW11)),"Tarih girilmedi",IFERROR(EDATE(CW11,57),"Tarih hatalı"))) | FJ11: =IF(B11="","",IF(NOT(ISNUMBER(DH11)),"Tarih girilmedi",IFERROR(EDATE(DH11,36),"Tarih hatalı"))) | FK11: =IF(B11="","",IF(NOT(ISNUMBER(DH11)),"Tarih girilmedi",IFERROR(EDATE(DH11,33),"Tarih hatalı"))) | FL11: =IF(B11="","",IF(NOT(ISNUMBER(BW11)),"Tarih girilmedi",IFERROR(EDATE(BW11,24),"Tarih hatalı"))) | FM11: =IF(B11="","",IF(NOT(ISNUMBER(BW11)),"Tarih girilmedi",IFERROR(EDATE(BW11,24)-45,"Tarih hatalı"))) | FN11: =IF(B11="","",IF(NOT(ISNUMBER(BM11)),"Tarih girilmedi",IFERROR(BM11-180,"Tarih hatalı"))) | FO11: =IF(OR(B11="",NOT(ISNUMBER(BM11))),"",BM11) | FP11: =IF(OR(B11="",NOT(ISNUMBER(BM11))),"",BM11-180) | FQ11: =IF(OR(B11="",NOT(ISNUMBER(BR11))),"",BR11) | FR11: =IF(OR(B11="",NOT(ISNUMBER(AL11))),"",AL11) | FS11: =IF(OR(B11="",NOT(ISNUMBER(CW11))),"",EDATE(CW11,60)) | FT11: =IF(OR(B11="",NOT(ISNUMBER(DH11))),"",EDATE(DH11,36)) | FU11: =IF(OR(B11="",NOT(ISNUMBER(BW11))),"",EDATE(BW11,24)) | FV11: =IF(OR(B11="",NOT(ISNUMBER(BX11))),"",BX11) | FW11: =IF(OR(B11="",NOT(ISNUMBER(EK11))),"",EDATE(EK11,12)) | FX11: =IF(OR(B11="",NOT(ISNUMBER(EL11))),"",EL11) | FY11: =IF(OR(B11="",NOT(ISNUMBER(EN11))),"",EDATE(EN11,12)) | FZ11: =IF(OR(B11="",NOT(ISNUMBER(EO11))),"",EO11) | GA11: =IF(OR(B11="",NOT(ISNUMBER(CK11))),"",CK11) | GB11: =IF(OR(B11="",NOT(ISNUMBER(CM11))),"",CM11) | GC11: =IF(OR(B11="",NOT(ISNUMBER(CQ11))),"",CQ11) | GD11: =IF(OR(B11="",NOT(ISNUMBER(EI11))),"",EI11) | GE11: =IF(OR(B11="",NOT(ISNUMBER(FA11))),"",FA11) | GF11: =IF(OR(B11="",NOT(ISNUMBER(ES11))),"",ES11) | GG11: =IF(OR(B11="",NOT(ISNUMBER(FB11))),"",FB11)
A12: 8 | C12: =IF(B12="","",((P12="Süresi geçti")+(P12="Yaklaşıyor")+(P12="Tarih hatalı"))+((Q12="Süresi geçti")+(Q12="Yaklaşıyor")+(Q12="Tarih hatalı"))+((R12="Süresi geçti")+(R12="Yaklaşıyor")+(R12="Tarih hatalı"))+((S12="Süresi geçti")+(S12="Yaklaşıyor")+(S12="Tarih hatalı"))+((T12="Süresi geçti")+(T12="Yaklaşıyor")+(T12="Tarih hatalı"))+((U12="Süresi geçti")+(U12="Yaklaşıyor")+(U12="Tarih hatalı"))+((V12="Süresi geçti")+(V12="Yaklaşıyor")+(V12="Tarih hatalı"))) | D12: =IF(OR(B12="",E12=""),"",INDEX($FO$4:$GG$4,1,MATCH(E12,FO12:GG12,0))) | E12: =IF(B12="","",IF(COUNT(FO12:GG12)=0,"",SMALL(FO12:GG12,1))) | F12: =IF(E12="","",E12-TODAY()) | P12: =IF(B12="","",IF(NOT(ISNUMBER(AL12)),"Tarih girilmedi",IFERROR(IF(TODAY()>AL12,"Süresi geçti",IF(TODAY()>=(AL12-60),"Yaklaşıyor","Takipte")),"Tarih hatalı"))) | Q12: =IF(B12="","",IF(NOT(ISNUMBER(EK12)),"Tarih girilmedi",IFERROR(IF(TODAY()>EDATE(EK12,12),"Süresi geçti",IF(TODAY()>=EDATE(EK12,11),"Yaklaşıyor","Takipte")),"Tarih hatalı"))) | R12: =IF(B12="","",IF(NOT(ISNUMBER(EN12)),"Tarih girilmedi",IFERROR(IF(TODAY()>EDATE(EN12,12),"Süresi geçti",IF(TODAY()>=EDATE(EN12,11),"Yaklaşıyor","Takipte")),"Tarih hatalı"))) | S12: =IF(B12="","",IF(NOT(ISNUMBER(CW12)),"Tarih girilmedi",IFERROR(IF(TODAY()>EDATE(CW12,60),"Süresi geçti",IF(TODAY()>=EDATE(CW12,57),"Yaklaşıyor","Takipte")),"Tarih hatalı"))) | T12: =IF(B12="","",IF(NOT(ISNUMBER(DH12)),"Tarih girilmedi",IFERROR(IF(TODAY()>EDATE(DH12,36),"Süresi geçti",IF(TODAY()>=EDATE(DH12,33),"Yaklaşıyor","Takipte")),"Tarih hatalı"))) | U12: =IF(B12="","",IF(NOT(ISNUMBER(BW12)),"Tarih girilmedi",IFERROR(IF(TODAY()>EDATE(BW12,24),"Süresi geçti",IF(TODAY()>=(EDATE(BW12,24)-45),"Yaklaşıyor","Takipte")),"Tarih hatalı"))) | V12: =IF(B12="","",IF(NOT(ISNUMBER(BM12)),"Tarih girilmedi",IFERROR(IF(TODAY()>BM12,"Süresi geçti",IF(TODAY()>=(BM12-180),"Yaklaşıyor","Takipte")),"Tarih hatalı"))) | FD12: =IF(B12="","",IF(NOT(ISNUMBER(EK12)),"Tarih girilmedi",IFERROR(EDATE(EK12,12),"Tarih hatalı"))) | FE12: =IF(B12="","",IF(NOT(ISNUMBER(EK12)),"Tarih girilmedi",IFERROR(EDATE(EK12,11),"Tarih hatalı"))) | FF12: =IF(B12="","",IF(NOT(ISNUMBER(EN12)),"Tarih girilmedi",IFERROR(EDATE(EN12,12),"Tarih hatalı"))) | FG12: =IF(B12="","",IF(NOT(ISNUMBER(EN12)),"Tarih girilmedi",IFERROR(EDATE(EN12,11),"Tarih hatalı"))) | FH12: =IF(B12="","",IF(NOT(ISNUMBER(CW12)),"Tarih girilmedi",IFERROR(EDATE(CW12,60),"Tarih hatalı"))) | FI12: =IF(B12="","",IF(NOT(ISNUMBER(CW12)),"Tarih girilmedi",IFERROR(EDATE(CW12,57),"Tarih hatalı"))) | FJ12: =IF(B12="","",IF(NOT(ISNUMBER(DH12)),"Tarih girilmedi",IFERROR(EDATE(DH12,36),"Tarih hatalı"))) | FK12: =IF(B12="","",IF(NOT(ISNUMBER(DH12)),"Tarih girilmedi",IFERROR(EDATE(DH12,33),"Tarih hatalı"))) | FL12: =IF(B12="","",IF(NOT(ISNUMBER(BW12)),"Tarih girilmedi",IFERROR(EDATE(BW12,24),"Tarih hatalı"))) | FM12: =IF(B12="","",IF(NOT(ISNUMBER(BW12)),"Tarih girilmedi",IFERROR(EDATE(BW12,24)-45,"Tarih hatalı"))) | FN12: =IF(B12="","",IF(NOT(ISNUMBER(BM12)),"Tarih girilmedi",IFERROR(BM12-180,"Tarih hatalı"))) | FO12: =IF(OR(B12="",NOT(ISNUMBER(BM12))),"",BM12) | FP12: =IF(OR(B12="",NOT(ISNUMBER(BM12))),"",BM12-180) | FQ12: =IF(OR(B12="",NOT(ISNUMBER(BR12))),"",BR12) | FR12: =IF(OR(B12="",NOT(ISNUMBER(AL12))),"",AL12) | FS12: =IF(OR(B12="",NOT(ISNUMBER(CW12))),"",EDATE(CW12,60)) | FT12: =IF(OR(B12="",NOT(ISNUMBER(DH12))),"",EDATE(DH12,36)) | FU12: =IF(OR(B12="",NOT(ISNUMBER(BW12))),"",EDATE(BW12,24)) | FV12: =IF(OR(B12="",NOT(ISNUMBER(BX12))),"",BX12) | FW12: =IF(OR(B12="",NOT(ISNUMBER(EK12))),"",EDATE(EK12,12)) | FX12: =IF(OR(B12="",NOT(ISNUMBER(EL12))),"",EL12) | FY12: =IF(OR(B12="",NOT(ISNUMBER(EN12))),"",EDATE(EN12,12)) | FZ12: =IF(OR(B12="",NOT(ISNUMBER(EO12))),"",EO12) | GA12: =IF(OR(B12="",NOT(ISNUMBER(CK12))),"",CK12) | GB12: =IF(OR(B12="",NOT(ISNUMBER(CM12))),"",CM12) | GC12: =IF(OR(B12="",NOT(ISNUMBER(CQ12))),"",CQ12) | GD12: =IF(OR(B12="",NOT(ISNUMBER(EI12))),"",EI12) | GE12: =IF(OR(B12="",NOT(ISNUMBER(FA12))),"",FA12) | GF12: =IF(OR(B12="",NOT(ISNUMBER(ES12))),"",ES12) | GG12: =IF(OR(B12="",NOT(ISNUMBER(FB12))),"",FB12)
A13: 9 | C13: =IF(B13="","",((P13="Süresi geçti")+(P13="Yaklaşıyor")+(P13="Tarih hatalı"))+((Q13="Süresi geçti")+(Q13="Yaklaşıyor")+(Q13="Tarih hatalı"))+((R13="Süresi geçti")+(R13="Yaklaşıyor")+(R13="Tarih hatalı"))+((S13="Süresi geçti")+(S13="Yaklaşıyor")+(S13="Tarih hatalı"))+((T13="Süresi geçti")+(T13="Yaklaşıyor")+(T13="Tarih hatalı"))+((U13="Süresi geçti")+(U13="Yaklaşıyor")+(U13="Tarih hatalı"))+((V13="Süresi geçti")+(V13="Yaklaşıyor")+(V13="Tarih hatalı"))) | D13: =IF(OR(B13="",E13=""),"",INDEX($FO$4:$GG$4,1,MATCH(E13,FO13:GG13,0))) | E13: =IF(B13="","",IF(COUNT(FO13:GG13)=0,"",SMALL(FO13:GG13,1))) | F13: =IF(E13="","",E13-TODAY()) | P13: =IF(B13="","",IF(NOT(ISNUMBER(AL13)),"Tarih girilmedi",IFERROR(IF(TODAY()>AL13,"Süresi geçti",IF(TODAY()>=(AL13-60),"Yaklaşıyor","Takipte")),"Tarih hatalı"))) | Q13: =IF(B13="","",IF(NOT(ISNUMBER(EK13)),"Tarih girilmedi",IFERROR(IF(TODAY()>EDATE(EK13,12),"Süresi geçti",IF(TODAY()>=EDATE(EK13,11),"Yaklaşıyor","Takipte")),"Tarih hatalı"))) | R13: =IF(B13="","",IF(NOT(ISNUMBER(EN13)),"Tarih girilmedi",IFERROR(IF(TODAY()>EDATE(EN13,12),"Süresi geçti",IF(TODAY()>=EDATE(EN13,11),"Yaklaşıyor","Takipte")),"Tarih hatalı"))) | S13: =IF(B13="","",IF(NOT(ISNUMBER(CW13)),"Tarih girilmedi",IFERROR(IF(TODAY()>EDATE(CW13,60),"Süresi geçti",IF(TODAY()>=EDATE(CW13,57),"Yaklaşıyor","Takipte")),"Tarih hatalı"))) | T13: =IF(B13="","",IF(NOT(ISNUMBER(DH13)),"Tarih girilmedi",IFERROR(IF(TODAY()>EDATE(DH13,36),"Süresi geçti",IF(TODAY()>=EDATE(DH13,33),"Yaklaşıyor","Takipte")),"Tarih hatalı"))) | U13: =IF(B13="","",IF(NOT(ISNUMBER(BW13)),"Tarih girilmedi",IFERROR(IF(TODAY()>EDATE(BW13,24),"Süresi geçti",IF(TODAY()>=(EDATE(BW13,24)-45),"Yaklaşıyor","Takipte")),"Tarih hatalı"))) | V13: =IF(B13="","",IF(NOT(ISNUMBER(BM13)),"Tarih girilmedi",IFERROR(IF(TODAY()>BM13,"Süresi geçti",IF(TODAY()>=(BM13-180),"Yaklaşıyor","Takipte")),"Tarih hatalı"))) | FD13: =IF(B13="","",IF(NOT(ISNUMBER(EK13)),"Tarih girilmedi",IFERROR(EDATE(EK13,12),"Tarih hatalı"))) | FE13: =IF(B13="","",IF(NOT(ISNUMBER(EK13)),"Tarih girilmedi",IFERROR(EDATE(EK13,11),"Tarih hatalı"))) | FF13: =IF(B13="","",IF(NOT(ISNUMBER(EN13)),"Tarih girilmedi",IFERROR(EDATE(EN13,12),"Tarih hatalı"))) | FG13: =IF(B13="","",IF(NOT(ISNUMBER(EN13)),"Tarih girilmedi",IFERROR(EDATE(EN13,11),"Tarih hatalı"))) | FH13: =IF(B13="","",IF(NOT(ISNUMBER(CW13)),"Tarih girilmedi",IFERROR(EDATE(CW13,60),"Tarih hatalı"))) | FI13: =IF(B13="","",IF(NOT(ISNUMBER(CW13)),"Tarih girilmedi",IFERROR(EDATE(CW13,57),"Tarih hatalı"))) | FJ13: =IF(B13="","",IF(NOT(ISNUMBER(DH13)),"Tarih girilmedi",IFERROR(EDATE(DH13,36),"Tarih hatalı"))) | FK13: =IF(B13="","",IF(NOT(ISNUMBER(DH13)),"Tarih girilmedi",IFERROR(EDATE(DH13,33),"Tarih hatalı"))) | FL13: =IF(B13="","",IF(NOT(ISNUMBER(BW13)),"Tarih girilmedi",IFERROR(EDATE(BW13,24),"Tarih hatalı"))) | FM13: =IF(B13="","",IF(NOT(ISNUMBER(BW13)),"Tarih girilmedi",IFERROR(EDATE(BW13,24)-45,"Tarih hatalı"))) | FN13: =IF(B13="","",IF(NOT(ISNUMBER(BM13)),"Tarih girilmedi",IFERROR(BM13-180,"Tarih hatalı"))) | FO13: =IF(OR(B13="",NOT(ISNUMBER(BM13))),"",BM13) | FP13: =IF(OR(B13="",NOT(ISNUMBER(BM13))),"",BM13-180) | FQ13: =IF(OR(B13="",NOT(ISNUMBER(BR13))),"",BR13) | FR13: =IF(OR(B13="",NOT(ISNUMBER(AL13))),"",AL13) | FS13: =IF(OR(B13="",NOT(ISNUMBER(CW13))),"",EDATE(CW13,60)) | FT13: =IF(OR(B13="",NOT(ISNUMBER(DH13))),"",EDATE(DH13,36)) | FU13: =IF(OR(B13="",NOT(ISNUMBER(BW13))),"",EDATE(BW13,24)) | FV13: =IF(OR(B13="",NOT(ISNUMBER(BX13))),"",BX13) | FW13: =IF(OR(B13="",NOT(ISNUMBER(EK13))),"",EDATE(EK13,12)) | FX13: =IF(OR(B13="",NOT(ISNUMBER(EL13))),"",EL13) | FY13: =IF(OR(B13="",NOT(ISNUMBER(EN13))),"",EDATE(EN13,12)) | FZ13: =IF(OR(B13="",NOT(ISNUMBER(EO13))),"",EO13) | GA13: =IF(OR(B13="",NOT(ISNUMBER(CK13))),"",CK13) | GB13: =IF(OR(B13="",NOT(ISNUMBER(CM13))),"",CM13) | GC13: =IF(OR(B13="",NOT(ISNUMBER(CQ13))),"",CQ13) | GD13: =IF(OR(B13="",NOT(ISNUMBER(EI13))),"",EI13) | GE13: =IF(OR(B13="",NOT(ISNUMBER(FA13))),"",FA13) | GF13: =IF(OR(B13="",NOT(ISNUMBER(ES13))),"",ES13) | GG13: =IF(OR(B13="",NOT(ISNUMBER(FB13))),"",FB13)
A14: 10 | C14: =IF(B14="","",((P14="Süresi geçti")+(P14="Yaklaşıyor")+(P14="Tarih hatalı"))+((Q14="Süresi geçti")+(Q14="Yaklaşıyor")+(Q14="Tarih hatalı"))+((R14="Süresi geçti")+(R14="Yaklaşıyor")+(R14="Tarih hatalı"))+((S14="Süresi geçti")+(S14="Yaklaşıyor")+(S14="Tarih hatalı"))+((T14="Süresi geçti")+(T14="Yaklaşıyor")+(T14="Tarih hatalı"))+((U14="Süresi geçti")+(U14="Yaklaşıyor")+(U14="Tarih hatalı"))+((V14="Süresi geçti")+(V14="Yaklaşıyor")+(V14="Tarih hatalı"))) | D14: =IF(OR(B14="",E14=""),"",INDEX($FO$4:$GG$4,1,MATCH(E14,FO14:GG14,0))) | E14: =IF(B14="","",IF(COUNT(FO14:GG14)=0,"",SMALL(FO14:GG14,1))) | F14: =IF(E14="","",E14-TODAY()) | P14: =IF(B14="","",IF(NOT(ISNUMBER(AL14)),"Tarih girilmedi",IFERROR(IF(TODAY()>AL14,"Süresi geçti",IF(TODAY()>=(AL14-60),"Yaklaşıyor","Takipte")),"Tarih hatalı"))) | Q14: =IF(B14="","",IF(NOT(ISNUMBER(EK14)),"Tarih girilmedi",IFERROR(IF(TODAY()>EDATE(EK14,12),"Süresi geçti",IF(TODAY()>=EDATE(EK14,11),"Yaklaşıyor","Takipte")),"Tarih hatalı"))) | R14: =IF(B14="","",IF(NOT(ISNUMBER(EN14)),"Tarih girilmedi",IFERROR(IF(TODAY()>EDATE(EN14,12),"Süresi geçti",IF(TODAY()>=EDATE(EN14,11),"Yaklaşıyor","Takipte")),"Tarih hatalı"))) | S14: =IF(B14="","",IF(NOT(ISNUMBER(CW14)),"Tarih girilmedi",IFERROR(IF(TODAY()>EDATE(CW14,60),"Süresi geçti",IF(TODAY()>=EDATE(CW14,57),"Yaklaşıyor","Takipte")),"Tarih hatalı"))) | T14: =IF(B14="","",IF(NOT(ISNUMBER(DH14)),"Tarih girilmedi",IFERROR(IF(TODAY()>EDATE(DH14,36),"Süresi geçti",IF(TODAY()>=EDATE(DH14,33),"Yaklaşıyor","Takipte")),"Tarih hatalı"))) | U14: =IF(B14="","",IF(NOT(ISNUMBER(BW14)),"Tarih girilmedi",IFERROR(IF(TODAY()>EDATE(BW14,24),"Süresi geçti",IF(TODAY()>=(EDATE(BW14,24)-45),"Yaklaşıyor","Takipte")),"Tarih hatalı"))) | V14: =IF(B14="","",IF(NOT(ISNUMBER(BM14)),"Tarih girilmedi",IFERROR(IF(TODAY()>BM14,"Süresi geçti",IF(TODAY()>=(BM14-180),"Yaklaşıyor","Takipte")),"Tarih hatalı"))) | FD14: =IF(B14="","",IF(NOT(ISNUMBER(EK14)),"Tarih girilmedi",IFERROR(EDATE(EK14,12),"Tarih hatalı"))) | FE14: =IF(B14="","",IF(NOT(ISNUMBER(EK14)),"Tarih girilmedi",IFERROR(EDATE(EK14,11),"Tarih hatalı"))) | FF14: =IF(B14="","",IF(NOT(ISNUMBER(EN14)),"Tarih girilmedi",IFERROR(EDATE(EN14,12),"Tarih hatalı"))) | FG14: =IF(B14="","",IF(NOT(ISNUMBER(EN14)),"Tarih girilmedi",IFERROR(EDATE(EN14,11),"Tarih hatalı"))) | FH14: =IF(B14="","",IF(NOT(ISNUMBER(CW14)),"Tarih girilmedi",IFERROR(EDATE(CW14,60),"Tarih hatalı"))) | FI14: =IF(B14="","",IF(NOT(ISNUMBER(CW14)),"Tarih girilmedi",IFERROR(EDATE(CW14,57),"Tarih hatalı"))) | FJ14: =IF(B14="","",IF(NOT(ISNUMBER(DH14)),"Tarih girilmedi",IFERROR(EDATE(DH14,36),"Tarih hatalı"))) | FK14: =IF(B14="","",IF(NOT(ISNUMBER(DH14)),"Tarih girilmedi",IFERROR(EDATE(DH14,33),"Tarih hatalı"))) | FL14: =IF(B14="","",IF(NOT(ISNUMBER(BW14)),"Tarih girilmedi",IFERROR(EDATE(BW14,24),"Tarih hatalı"))) | FM14: =IF(B14="","",IF(NOT(ISNUMBER(BW14)),"Tarih girilmedi",IFERROR(EDATE(BW14,24)-45,"Tarih hatalı"))) | FN14: =IF(B14="","",IF(NOT(ISNUMBER(BM14)),"Tarih girilmedi",IFERROR(BM14-180,"Tarih hatalı"))) | FO14: =IF(OR(B14="",NOT(ISNUMBER(BM14))),"",BM14) | FP14: =IF(OR(B14="",NOT(ISNUMBER(BM14))),"",BM14-180) | FQ14: =IF(OR(B14="",NOT(ISNUMBER(BR14))),"",BR14) | FR14: =IF(OR(B14="",NOT(ISNUMBER(AL14))),"",AL14) | FS14: =IF(OR(B14="",NOT(ISNUMBER(CW14))),"",EDATE(CW14,60)) | FT14: =IF(OR(B14="",NOT(ISNUMBER(DH14))),"",EDATE(DH14,36)) | FU14: =IF(OR(B14="",NOT(ISNUMBER(BW14))),"",EDATE(BW14,24)) | FV14: =IF(OR(B14="",NOT(ISNUMBER(BX14))),"",BX14) | FW14: =IF(OR(B14="",NOT(ISNUMBER(EK14))),"",EDATE(EK14,12)) | FX14: =IF(OR(B14="",NOT(ISNUMBER(EL14))),"",EL14) | FY14: =IF(OR(B14="",NOT(ISNUMBER(EN14))),"",EDATE(EN14,12)) | FZ14: =IF(OR(B14="",NOT(ISNUMBER(EO14))),"",EO14) | GA14: =IF(OR(B14="",NOT(ISNUMBER(CK14))),"",CK14) | GB14: =IF(OR(B14="",NOT(ISNUMBER(CM14))),"",CM14) | GC14: =IF(OR(B14="",NOT(ISNUMBER(CQ14))),"",CQ14) | GD14: =IF(OR(B14="",NOT(ISNUMBER(EI14))),"",EI14) | GE14: =IF(OR(B14="",NOT(ISNUMBER(FA14))),"",FA14) | GF14: =IF(OR(B14="",NOT(ISNUMBER(ES14))),"",ES14) | GG14: =IF(OR(B14="",NOT(ISNUMBER(FB14))),"",FB14)
A15: 11 | C15: =IF(B15="","",((P15="Süresi geçti")+(P15="Yaklaşıyor")+(P15="Tarih hatalı"))+((Q15="Süresi geçti")+(Q15="Yaklaşıyor")+(Q15="Tarih hatalı"))+((R15="Süresi geçti")+(R15="Yaklaşıyor")+(R15="Tarih hatalı"))+((S15="Süresi geçti")+(S15="Yaklaşıyor")+(S15="Tarih hatalı"))+((T15="Süresi geçti")+(T15="Yaklaşıyor")+(T15="Tarih hatalı"))+((U15="Süresi geçti")+(U15="Yaklaşıyor")+(U15="Tarih hatalı"))+((V15="Süresi geçti")+(V15="Yaklaşıyor")+(V15="Tarih hatalı"))) | D15: =IF(OR(B15="",E15=""),"",INDEX($FO$4:$GG$4,1,MATCH(E15,FO15:GG15,0))) | E15: =IF(B15="","",IF(COUNT(FO15:GG15)=0,"",SMALL(FO15:GG15,1))) | F15: =IF(E15="","",E15-TODAY()) | P15: =IF(B15="","",IF(NOT(ISNUMBER(AL15)),"Tarih girilmedi",IFERROR(IF(TODAY()>AL15,"Süresi geçti",IF(TODAY()>=(AL15-60),"Yaklaşıyor","Takipte")),"Tarih hatalı"))) | Q15: =IF(B15="","",IF(NOT(ISNUMBER(EK15)),"Tarih girilmedi",IFERROR(IF(TODAY()>EDATE(EK15,12),"Süresi geçti",IF(TODAY()>=EDATE(EK15,11),"Yaklaşıyor","Takipte")),"Tarih hatalı"))) | R15: =IF(B15="","",IF(NOT(ISNUMBER(EN15)),"Tarih girilmedi",IFERROR(IF(TODAY()>EDATE(EN15,12),"Süresi geçti",IF(TODAY()>=EDATE(EN15,11),"Yaklaşıyor","Takipte")),"Tarih hatalı"))) | S15: =IF(B15="","",IF(NOT(ISNUMBER(CW15)),"Tarih girilmedi",IFERROR(IF(TODAY()>EDATE(CW15,60),"Süresi geçti",IF(TODAY()>=EDATE(CW15,57),"Yaklaşıyor","Takipte")),"Tarih hatalı"))) | T15: =IF(B15="","",IF(NOT(ISNUMBER(DH15)),"Tarih girilmedi",IFERROR(IF(TODAY()>EDATE(DH15,36),"Süresi geçti",IF(TODAY()>=EDATE(DH15,33),"Yaklaşıyor","Takipte")),"Tarih hatalı"))) | U15: =IF(B15="","",IF(NOT(ISNUMBER(BW15)),"Tarih girilmedi",IFERROR(IF(TODAY()>EDATE(BW15,24),"Süresi geçti",IF(TODAY()>=(EDATE(BW15,24)-45),"Yaklaşıyor","Takipte")),"Tarih hatalı"))) | V15: =IF(B15="","",IF(NOT(ISNUMBER(BM15)),"Tarih girilmedi",IFERROR(IF(TODAY()>BM15,"Süresi geçti",IF(TODAY()>=(BM15-180),"Yaklaşıyor","Takipte")),"Tarih hatalı"))) | FD15: =IF(B15="","",IF(NOT(ISNUMBER(EK15)),"Tarih girilmedi",IFERROR(EDATE(EK15,12),"Tarih hatalı"))) | FE15: =IF(B15="","",IF(NOT(ISNUMBER(EK15)),"Tarih girilmedi",IFERROR(EDATE(EK15,11),"Tarih hatalı"))) | FF15: =IF(B15="","",IF(NOT(ISNUMBER(EN15)),"Tarih girilmedi",IFERROR(EDATE(EN15,12),"Tarih hatalı"))) | FG15: =IF(B15="","",IF(NOT(ISNUMBER(EN15)),"Tarih girilmedi",IFERROR(EDATE(EN15,11),"Tarih hatalı"))) | FH15: =IF(B15="","",IF(NOT(ISNUMBER(CW15)),"Tarih girilmedi",IFERROR(EDATE(CW15,60),"Tarih hatalı"))) | FI15: =IF(B15="","",IF(NOT(ISNUMBER(CW15)),"Tarih girilmedi",IFERROR(EDATE(CW15,57),"Tarih hatalı"))) | FJ15: =IF(B15="","",IF(NOT(ISNUMBER(DH15)),"Tarih girilmedi",IFERROR(EDATE(DH15,36),"Tarih hatalı"))) | FK15: =IF(B15="","",IF(NOT(ISNUMBER(DH15)),"Tarih girilmedi",IFERROR(EDATE(DH15,33),"Tarih hatalı"))) | FL15: =IF(B15="","",IF(NOT(ISNUMBER(BW15)),"Tarih girilmedi",IFERROR(EDATE(BW15,24),"Tarih hatalı"))) | FM15: =IF(B15="","",IF(NOT(ISNUMBER(BW15)),"Tarih girilmedi",IFERROR(EDATE(BW15,24)-45,"Tarih hatalı"))) | FN15: =IF(B15="","",IF(NOT(ISNUMBER(BM15)),"Tarih girilmedi",IFERROR(BM15-180,"Tarih hatalı"))) | FO15: =IF(OR(B15="",NOT(ISNUMBER(BM15))),"",BM15) | FP15: =IF(OR(B15="",NOT(ISNUMBER(BM15))),"",BM15-180) | FQ15: =IF(OR(B15="",NOT(ISNUMBER(BR15))),"",BR15) | FR15: =IF(OR(B15="",NOT(ISNUMBER(AL15))),"",AL15) | FS15: =IF(OR(B15="",NOT(ISNUMBER(CW15))),"",EDATE(CW15,60)) | FT15: =IF(OR(B15="",NOT(ISNUMBER(DH15))),"",EDATE(DH15,36)) | FU15: =IF(OR(B15="",NOT(ISNUMBER(BW15))),"",EDATE(BW15,24)) | FV15: =IF(OR(B15="",NOT(ISNUMBER(BX15))),"",BX15) | FW15: =IF(OR(B15="",NOT(ISNUMBER(EK15))),"",EDATE(EK15,12)) | FX15: =IF(OR(B15="",NOT(ISNUMBER(EL15))),"",EL15) | FY15: =IF(OR(B15="",NOT(ISNUMBER(EN15))),"",EDATE(EN15,12)) | FZ15: =IF(OR(B15="",NOT(ISNUMBER(EO15))),"",EO15) | GA15: =IF(OR(B15="",NOT(ISNUMBER(CK15))),"",CK15) | GB15: =IF(OR(B15="",NOT(ISNUMBER(CM15))),"",CM15) | GC15: =IF(OR(B15="",NOT(ISNUMBER(CQ15))),"",CQ15) | GD15: =IF(OR(B15="",NOT(ISNUMBER(EI15))),"",EI15) | GE15: =IF(OR(B15="",NOT(ISNUMBER(FA15))),"",FA15) | GF15: =IF(OR(B15="",NOT(ISNUMBER(ES15))),"",ES15) | GG15: =IF(OR(B15="",NOT(ISNUMBER(FB15))),"",FB15)
A16: 12 | C16: =IF(B16="","",((P16="Süresi geçti")+(P16="Yaklaşıyor")+(P16="Tarih hatalı"))+((Q16="Süresi geçti")+(Q16="Yaklaşıyor")+(Q16="Tarih hatalı"))+((R16="Süresi geçti")+(R16="Yaklaşıyor")+(R16="Tarih hatalı"))+((S16="Süresi geçti")+(S16="Yaklaşıyor")+(S16="Tarih hatalı"))+((T16="Süresi geçti")+(T16="Yaklaşıyor")+(T16="Tarih hatalı"))+((U16="Süresi geçti")+(U16="Yaklaşıyor")+(U16="Tarih hatalı"))+((V16="Süresi geçti")+(V16="Yaklaşıyor")+(V16="Tarih hatalı"))) | D16: =IF(OR(B16="",E16=""),"",INDEX($FO$4:$GG$4,1,MATCH(E16,FO16:GG16,0))) | E16: =IF(B16="","",IF(COUNT(FO16:GG16)=0,"",SMALL(FO16:GG16,1))) | F16: =IF(E16="","",E16-TODAY()) | P16: =IF(B16="","",IF(NOT(ISNUMBER(AL16)),"Tarih girilmedi",IFERROR(IF(TODAY()>AL16,"Süresi geçti",IF(TODAY()>=(AL16-60),"Yaklaşıyor","Takipte")),"Tarih hatalı"))) | Q16: =IF(B16="","",IF(NOT(ISNUMBER(EK16)),"Tarih girilmedi",IFERROR(IF(TODAY()>EDATE(EK16,12),"Süresi geçti",IF(TODAY()>=EDATE(EK16,11),"Yaklaşıyor","Takipte")),"Tarih hatalı"))) | R16: =IF(B16="","",IF(NOT(ISNUMBER(EN16)),"Tarih girilmedi",IFERROR(IF(TODAY()>EDATE(EN16,12),"Süresi geçti",IF(TODAY()>=EDATE(EN16,11),"Yaklaşıyor","Takipte")),"Tarih hatalı"))) | S16: =IF(B16="","",IF(NOT(ISNUMBER(CW16)),"Tarih girilmedi",IFERROR(IF(TODAY()>EDATE(CW16,60),"Süresi geçti",IF(TODAY()>=EDATE(CW16,57),"Yaklaşıyor","Takipte")),"Tarih hatalı"))) | T16: =IF(B16="","",IF(NOT(ISNUMBER(DH16)),"Tarih girilmedi",IFERROR(IF(TODAY()>EDATE(DH16,36),"Süresi geçti",IF(TODAY()>=EDATE(DH16,33),"Yaklaşıyor","Takipte")),"Tarih hatalı"))) | U16: =IF(B16="","",IF(NOT(ISNUMBER(BW16)),"Tarih girilmedi",IFERROR(IF(TODAY()>EDATE(BW16,24),"Süresi geçti",IF(TODAY()>=(EDATE(BW16,24)-45),"Yaklaşıyor","Takipte")),"Tarih hatalı"))) | V16: =IF(B16="","",IF(NOT(ISNUMBER(BM16)),"Tarih girilmedi",IFERROR(IF(TODAY()>BM16,"Süresi geçti",IF(TODAY()>=(BM16-180),"Yaklaşıyor","Takipte")),"Tarih hatalı"))) | FD16: =IF(B16="","",IF(NOT(ISNUMBER(EK16)),"Tarih girilmedi",IFERROR(EDATE(EK16,12),"Tarih hatalı"))) | FE16: =IF(B16="","",IF(NOT(ISNUMBER(EK16)),"Tarih girilmedi",IFERROR(EDATE(EK16,11),"Tarih hatalı"))) | FF16: =IF(B16="","",IF(NOT(ISNUMBER(EN16)),"Tarih girilmedi",IFERROR(EDATE(EN16,12),"Tarih hatalı"))) | FG16: =IF(B16="","",IF(NOT(ISNUMBER(EN16)),"Tarih girilmedi",IFERROR(EDATE(EN16,11),"Tarih hatalı"))) | FH16: =IF(B16="","",IF(NOT(ISNUMBER(CW16)),"Tarih girilmedi",IFERROR(EDATE(CW16,60),"Tarih hatalı"))) | FI16: =IF(B16="","",IF(NOT(ISNUMBER(CW16)),"Tarih girilmedi",IFERROR(EDATE(CW16,57),"Tarih hatalı"))) | FJ16: =IF(B16="","",IF(NOT(ISNUMBER(DH16)),"Tarih girilmedi",IFERROR(EDATE(DH16,36),"Tarih hatalı"))) | FK16: =IF(B16="","",IF(NOT(ISNUMBER(DH16)),"Tarih girilmedi",IFERROR(EDATE(DH16,33),"Tarih hatalı"))) | FL16: =IF(B16="","",IF(NOT(ISNUMBER(BW16)),"Tarih girilmedi",IFERROR(EDATE(BW16,24),"Tarih hatalı"))) | FM16: =IF(B16="","",IF(NOT(ISNUMBER(BW16)),"Tarih girilmedi",IFERROR(EDATE(BW16,24)-45,"Tarih hatalı"))) | FN16: =IF(B16="","",IF(NOT(ISNUMBER(BM16)),"Tarih girilmedi",IFERROR(BM16-180,"Tarih hatalı"))) | FO16: =IF(OR(B16="",NOT(ISNUMBER(BM16))),"",BM16) | FP16: =IF(OR(B16="",NOT(ISNUMBER(BM16))),"",BM16-180) | FQ16: =IF(OR(B16="",NOT(ISNUMBER(BR16))),"",BR16) | FR16: =IF(OR(B16="",NOT(ISNUMBER(AL16))),"",AL16) | FS16: =IF(OR(B16="",NOT(ISNUMBER(CW16))),"",EDATE(CW16,60)) | FT16: =IF(OR(B16="",NOT(ISNUMBER(DH16))),"",EDATE(DH16,36)) | FU16: =IF(OR(B16="",NOT(ISNUMBER(BW16))),"",EDATE(BW16,24)) | FV16: =IF(OR(B16="",NOT(ISNUMBER(BX16))),"",BX16) | FW16: =IF(OR(B16="",NOT(ISNUMBER(EK16))),"",EDATE(EK16,12)) | FX16: =IF(OR(B16="",NOT(ISNUMBER(EL16))),"",EL16) | FY16: =IF(OR(B16="",NOT(ISNUMBER(EN16))),"",EDATE(EN16,12)) | FZ16: =IF(OR(B16="",NOT(ISNUMBER(EO16))),"",EO16) | GA16: =IF(OR(B16="",NOT(ISNUMBER(CK16))),"",CK16) | GB16: =IF(OR(B16="",NOT(ISNUMBER(CM16))),"",CM16) | GC16: =IF(OR(B16="",NOT(ISNUMBER(CQ16))),"",CQ16) | GD16: =IF(OR(B16="",NOT(ISNUMBER(EI16))),"",EI16) | GE16: =IF(OR(B16="",NOT(ISNUMBER(FA16))),"",FA16) | GF16: =IF(OR(B16="",NOT(ISNUMBER(ES16))),"",ES16) | GG16: =IF(OR(B16="",NOT(ISNUMBER(FB16))),"",FB16)
... A44: 40 | C44: =IF(B44="","",((P44="Süresi geçti")+(P44="Yaklaşıyor")+(P44="Tarih hatalı"))+((Q44="Süresi geçti")+(Q44="Yaklaşıyor")+(Q44="Tarih hatalı"))+((R44="Süresi geçti")+(R44="Yaklaşıyor")+(R44="Tarih hatalı"))+((S44="Süresi geçti")+(S44="Yaklaşıyor")+(S44="Tarih hatalı"))+((T44="Süresi geçti")+(T44="Yaklaşıyor")+(T44="Tarih hatalı"))+((U44="Süresi geçti")+(U44="Yaklaşıyor")+(U44="Tarih hatalı"))+((V44="Süresi geçti")+(V44="Yaklaşıyor")+(V44="Tarih hatalı"))) | D44: =IF(OR(B44="",E44=""),"",INDEX($FO$4:$GG$4,1,MATCH(E44,FO44:GG44,0))) | E44: =IF(B44="","",IF(COUNT(FO44:GG44)=0,"",SMALL(FO44:GG44,1))) | F44: =IF(E44="","",E44-TODAY()) | P44: =IF(B44="","",IF(NOT(ISNUMBER(AL44)),"Tarih girilmedi",IFERROR(IF(TODAY()>AL44,"Süresi geçti",IF(TODAY()>=(AL44-60),"Yaklaşıyor","Takipte")),"Tarih hatalı"))) | Q44: =IF(B44="","",IF(NOT(ISNUMBER(EK44)),"Tarih girilmedi",IFERROR(IF(TODAY()>EDATE(EK44,12),"Süresi geçti",IF(TODAY()>=EDATE(EK44,11),"Yaklaşıyor","Takipte")),"Tarih hatalı"))) | R44: =IF(B44="","",IF(NOT(ISNUMBER(EN44)),"Tarih girilmedi",IFERROR(IF(TODAY()>EDATE(EN44,12),"Süresi geçti",IF(TODAY()>=EDATE(EN44,11),"Yaklaşıyor","Takipte")),"Tarih hatalı"))) | S44: =IF(B44="","",IF(NOT(ISNUMBER(CW44)),"Tarih girilmedi",IFERROR(IF(TODAY()>EDATE(CW44,60),"Süresi geçti",IF(TODAY()>=EDATE(CW44,57),"Yaklaşıyor","Takipte")),"Tarih hatalı"))) | T44: =IF(B44="","",IF(NOT(ISNUMBER(DH44)),"Tarih girilmedi",IFERROR(IF(TODAY()>EDATE(DH44,36),"Süresi geçti",IF(TODAY()>=EDATE(DH44,33),"Yaklaşıyor","Takipte")),"Tarih hatalı"))) | U44: =IF(B44="","",IF(NOT(ISNUMBER(BW44)),"Tarih girilmedi",IFERROR(IF(TODAY()>EDATE(BW44,24),"Süresi geçti",IF(TODAY()>=(EDATE(BW44,24)-45),"Yaklaşıyor","Takipte")),"Tarih hatalı"))) | V44: =IF(B44="","",IF(NOT(ISNUMBER(BM44)),"Tarih girilmedi",IFERROR(IF(TODAY()>BM44,"Süresi geçti",IF(TODAY()>=(BM44-180),"Yaklaşıyor","Takipte")),"Tarih hatalı"))) | FD44: =IF(B44="","",IF(NOT(ISNUMBER(EK44)),"Tarih girilmedi",IFERROR(EDATE(EK44,12),"Tarih hatalı"))) | FE44: =IF(B44="","",IF(NOT(ISNUMBER(EK44)),"Tarih girilmedi",IFERROR(EDATE(EK44,11),"Tarih hatalı"))) | FF44: =IF(B44="","",IF(NOT(ISNUMBER(EN44)),"Tarih girilmedi",IFERROR(EDATE(EN44,12),"Tarih hatalı"))) | FG44: =IF(B44="","",IF(NOT(ISNUMBER(EN44)),"Tarih girilmedi",IFERROR(EDATE(EN44,11),"Tarih hatalı"))) | FH44: =IF(B44="","",IF(NOT(ISNUMBER(CW44)),"Tarih girilmedi",IFERROR(EDATE(CW44,60),"Tarih hatalı"))) | FI44: =IF(B44="","",IF(NOT(ISNUMBER(CW44)),"Tarih girilmedi",IFERROR(EDATE(CW44,57),"Tarih hatalı"))) | FJ44: =IF(B44="","",IF(NOT(ISNUMBER(DH44)),"Tarih girilmedi",IFERROR(EDATE(DH44,36),"Tarih hatalı"))) | FK44: =IF(B44="","",IF(NOT(ISNUMBER(DH44)),"Tarih girilmedi",IFERROR(EDATE(DH44,33),"Tarih hatalı"))) | FL44: =IF(B44="","",IF(NOT(ISNUMBER(BW44)),"Tarih girilmedi",IFERROR(EDATE(BW44,24),"Tarih hatalı"))) | FM44: =IF(B44="","",IF(NOT(ISNUMBER(BW44)),"Tarih girilmedi",IFERROR(EDATE(BW44,24)-45,"Tarih hatalı"))) | FN44: =IF(B44="","",IF(NOT(ISNUMBER(BM44)),"Tarih girilmedi",IFERROR(BM44-180,"Tarih hatalı"))) | FO44: =IF(OR(B44="",NOT(ISNUMBER(BM44))),"",BM44) | FP44: =IF(OR(B44="",NOT(ISNUMBER(BM44))),"",BM44-180) | FQ44: =IF(OR(B44="",NOT(ISNUMBER(BR44))),"",BR44) | FR44: =IF(OR(B44="",NOT(ISNUMBER(AL44))),"",AL44) | FS44: =IF(OR(B44="",NOT(ISNUMBER(CW44))),"",EDATE(CW44,60)) | FT44: =IF(OR(B44="",NOT(ISNUMBER(DH44))),"",EDATE(DH44,36)) | FU44: =IF(OR(B44="",NOT(ISNUMBER(BW44))),"",EDATE(BW44,24)) | FV44: =IF(OR(B44="",NOT(ISNUMBER(BX44))),"",BX44) | FW44: =IF(OR(B44="",NOT(ISNUMBER(EK44))),"",EDATE(EK44,12)) | FX44: =IF(OR(B44="",NOT(ISNUMBER(EL44))),"",EL44) | FY44: =IF(OR(B44="",NOT(ISNUMBER(EN44))),"",EDATE(EN44,12)) | FZ44: =IF(OR(B44="",NOT(ISNUMBER(EO44))),"",EO44) | GA44: =IF(OR(B44="",NOT(ISNUMBER(CK44))),"",CK44) | GB44: =IF(OR(B44="",NOT(ISNUMBER(CM44))),"",CM44) | GC44: =IF(OR(B44="",NOT(ISNUMBER(CQ44))),"",CQ44) | GD44: =IF(OR(B44="",NOT(ISNUMBER(EI44))),"",EI44) | GE44: =IF(OR(B44="",NOT(ISNUMBER(FA44))),"",FA44) | GF44: =IF(OR(B44="",NOT(ISNUMBER(ES44))),"",ES44) | GG44: =IF(OR(B44="",NOT(ISNUMBER(FB44))),"",FB44)

Sheet Yaklaşan işler
A1: YAKLAŞAN VE GECİKEN İŞLER
A2: Süresi geçen | B2: =COUNTIF(F5:F764,"Süresi geçti") | C2: 30 gün içinde | D2: =COUNTIF(F5:F764,"30 gün içinde") | E2: 90 gün içinde | F2: =COUNTIF(F5:F764,"90 gün içinde") | G2: Durum sütunundan süzün. Boş satırlar tarihi girilmemiş işlerdir.
A4: Firma | B4: İl | C4: İş | D4: Tarih | E4: Kalan gün | F4: Durum | G4: Dosya durumu
A5: =IF(Firmalar!$B$5="","",Firmalar!$B$5) | B5: =IF(Firmalar!$B$5="","",Firmalar!$I$5) | C5: Çevre izni bitiş | D5: =IF(Firmalar!$B$5="","",Firmalar!$FO$5) | E5: =IF(OR(A5="",D5=""),"",D5-TODAY()) | F5: =IF(OR(A5="",D5=""),"",IF(D5<TODAY(),"Süresi geçti",IF(D5<=TODAY()+30,"30 gün içinde",IF(D5<=TODAY()+90,"90 gün içinde","İleride")))) | G5: =IF(A5="","",Firmalar!$H$5)
A6: =IF(Firmalar!$B$5="","",Firmalar!$B$5) | B6: =IF(Firmalar!$B$5="","",Firmalar!$I$5) | C6: Çevre izni başvurusu | D6: =IF(Firmalar!$B$5="","",Firmalar!$FP$5) | E6: =IF(OR(A6="",D6=""),"",D6-TODAY()) | F6: =IF(OR(A6="",D6=""),"",IF(D6<TODAY(),"Süresi geçti",IF(D6<=TODAY()+30,"30 gün içinde",IF(D6<=TODAY()+90,"90 gün içinde","İleride")))) | G6: =IF(A6="","",Firmalar!$H$5)
