Workbook

Sheet Ozet
A1: GÜNDÜZ MEY-PAK AKDENİZ ŞUBESİ — ÇEVRE TAKİP ÖZETİ
A2: Hazırlanma: 30.09.2026 | Dayanak: kimlik belgesi, proje onayı, 04.09.2026 iç tetkik, 24.09.2026 aylık faaliyet raporu | Bu sayfa saha ölçümü değildir.
A4: TESİS
A5: Unvan | B5: Gündüz Mey-Pak Gıda İnş. Taş. Oto. Pet. Ürün. Tur. Tic. Ltd. Şti. Akdeniz Şubesi
A6: Adres | B6: Kulak Mahallesi, İnönü Bulvarı No: 120 A, Akdeniz / Mersin
A7: ÇKN / Vergi | B7: 3069574032 / Kızılbey VD 4300580693
A8: Faaliyet | B8: Narenciye, sebze ve meyve yıkama, boyutlandırma, sarartma, mumlama, ambalajlama, soğuk hava depolama
A9: ÇİLY yeri | B9: Ek-1 madde 7.9 — çevre izni konusu şu an yalnızca atıksu deşarjı
A10: AAT | B10: 90 m³/gün kurulu | fiziksel + biyolojik (klasik aktif çamur) + klor dezenfeksiyonu | dengeleme havuzu
A11: Alıcı ortam | B11: Nacarlı Deresi | Doğu Akdeniz Havzası
A12: Deşarj standardı | B12: SKKY Tablo 5.9 — 2 saatlik kompozit: KOİ 150 mg/L, AKM 200 mg/L, pH 6-9
A13: İç izleme | B13: Fiili debi 51-200 m³/gün bandında ise iki ayda bir. Tablo 5.9’daki üç parametrenin üçü de her seferinde bakılır.
A14: Belge durumu | B14: Atıksu deşarjı konulu GFB 26.08.2027’ye kadar. Beş yıllık çevre izin çıktısı bu dosyada yok; e-İzin’den teyit edilecek.
A16: AÇIK İŞ VE SÜRE SAYACI (diğer sayfalardaki durum hücrelerinden hesaplanır)
A17: Kritik ve tamamlanmamış iş | B17: =COUNTIFS(Yapilacaklar!B5:B40,"Kritik",Yapilacaklar!I5:I40,"<>Tamamlandı")
A18: Yüksek öncelik, tamamlanmamış | B18: =COUNTIFS(Yapilacaklar!B5:B40,"Yüksek",Yapilacaklar!I5:I40,"<>Tamamlandı")
A19: Süresi geçmiş belge | B19: =COUNTIF(BelgeTakvimi!G5:G30,"SÜRESİ GEÇTİ")
A20: 60 gün içinde dolacak belge | B20: =COUNTIF(BelgeTakvimi!G5:G30,"60 GÜN İÇİNDE")
A21: İç izlemede limiti aşan kampanya | B21: =COUNTIF(IcIzleme!R5:R20,"AŞIM")
A23: ÖNCE BUNLAR
A24: 1 Yıkama, durulama ve mumlama sularının tamamı AAT’ye gidiyor mu? İç tetkik 6.1.3 ile 6.1.4 bu konuda çelişiyor. Hat yerinde yürünecek.
A25: 2 Eylül 2026 iç izleme alınmış deniyor; analiz raporu dosyada yok. Rapor bulunacak ya da numune hemen planlanacak. Kıyas: KOİ 150, AKM 200, pH 6-9.
A26: 3 Kimlik belgesinde tesis sorumlusu boş. Biyolojik arıtma ve 90 m³/gün bu tesisi B sınıfına sokar. Çevre görevlisi bu kadronun yerine geçmez.
A27: 4 Tehlikeli atık sözleşmesi yok, çamur 19 08 13* kodlu ve dönemde analiz yok. Sözleşme ve çamur karakterizasyonu birlikte kapatılacak.
A28: 5 Beş yıllık atıksu çevre izin çıktısı dosyada yok. GFB 26.08.2027’de bitiyor. e-İzin ekini indirin; ek, bu dosyadaki limiti ezer.
A30: Sayfalar: Tesis kimliği, Yapılacaklar, Belge takvimi, Aylık kontrol, İç izleme, Günlük işletme, Su dengesi, Atık takip, Uygunsuzluk, Notlar. Durum hücrelerini listeden seçin. Tamamlanan işin kanıt dosya adını yazın. Kayıtlar beş yıl saklanır.

Sheet Tesis
A1: TESİS KİMLİĞİ VE ATIKSU PROSESİ
A2: Kaynak belgelerin özeti. Çelişen alanlar sarıdır; asıl evrakla düzeltilmeden denetime götürülmez.
A4: Alan | B4: Belgedeki değer | C4: Kaynak | D4: Danışman notu
A5: Unvan | B5: Gündüz Mey-Pak Gıda İnş. Taş. Oto. Pet. Ürün. Tur. Tic. Ltd. Şti. Akdeniz Şubesi | C5: Kimlik, proje onayı, iç tetkik, aylık rapor | D5: Dört belgede unvan aynı.
A6: Adres | B6: Kulak Mah. İnönü Bulvarı No: 120 A, Akdeniz / Mersin | C6: Kimlik belgesi | D6: Tapu 154 ada, 8 ve 9 parsel (iç tetkik).
A7: İl / ilçe | B7: Mersin / Akdeniz | C7: Kimlik belgesi
A8: Vergi dairesi ve no | B8: Kızılbey VD / 4300580693 | C8: İç tetkik
A9: Çevre kimlik no | B9: 3069574032 | C9: İç tetkik, GFB belge no kökü
A10: NACE | B10: 46.31.03 Diğer taze meyve sebze toptan ticareti | C10: İç tetkik | D10: Fiili iş yıkama, mumlama ve paketleme. Beyanlarda faaliyet tanımı aynı kalsın.
A11: Çalışma | B11: Sürekli, 1 vardiya | C11: İç tetkik
A12: Personel | B12: Aylık rapor: 49. İç tetkik: idari 1, mühendis 1, işçi 58, toplam 60. | C12: 24.09.2026 aylık rapor ve 04.09.2026 iç tetkik | D12: Çelişki. SGK listesiyle netleştirin. Su verimliliği muafiyeti 50 kişinin altına bağlanmış.
A13: Alan | B13: Açık 9.730 m², kapalı 8.800 m², toplam 18.530 m². Mücavir alan. | C13: İç tetkik
A14: Yıllık kapasite | B14: Ambalajlama ve dolum 1.152.000 kg/yıl. Mumlama ve sarartma 26.880.000 kg/yıl. | C14: Kapasite raporu, iç tetkik | D14: Kapasite raporu 13.03.2025 / 150437, geçerlilik 03.03.2027.
A15: ÇED | B15: 24.02.2025, E-23645791-220.03-11844865. Yıkama, boyutlandırma, sarartma, mumlama, ambalajlama, iletme ve soğuk hava depolama için ÇED kapsam dışı. | C15: İç tetkik 6.1 | D15: Kapasite veya proses değişirse karar yenilenir.
A16: ÇİLY | B16: Ek-1 liste, madde 7.9. Üretim kapasitesi 100 ton/gün üzeri bitkisel ürün işleme ve ambalajlama. | C16: Aylık rapor ve iç tetkik | D16: İzin konusu belgelerde yalnızca atıksu deşarjı.
A17: GFB | B17: 26.08.2026 tarihli 58003700-150/E.5093. Belge no 3069574032.1.1. Geçerlilik 26.08.2027. Konu: Atıksu deşarjı. | C17: Aylık rapor C.1 ve iç tetkik 6.3 | D17: Beş yıllık çevre izin belgesi bu setin içinde yok.
A18: Uygunluk yazısı | B18: 07.08.2026. Aylık raporda E.944, iç tetkik sonucunda E.9446 ifadesi var. Başvuru 05.06.2026 / 700227. | C18: Aylık rapor C.2, iç tetkik sonuç | D18: Sayılar tutmuyor. İmzalı üst yazı dosyalansın, raporlardaki sayı ona çekilsin.
A19: AAT proje onayı | B19: 15.08.2025, E-27907008-100-13239842. Form belge no AAT03608. Hazırlayan: Bentos. Onay: İl Müdürü Hasan Alan. | C19: Proje onay yazısı ve Ek-1 form | D19: İç tetkik 6.5’te sayı 13239847 yazılmış. Resmi yazıdaki 13239842 esas alınsın.
A20: AAT kimlik | B20: 33.25-3069574032-344. Düzenleme ve güncelleme 10.09.2025. Üst yazı E.13621421. | C20: Kimlik belgesi | D20: Tesis sorumlusu alanları boş.
A21: İşletmeye alma / inşaat | B21: İşletmeye alma 15.08.2025. İnşaat bitiş 01.01.2000. | C21: Kimlik belgesi | D21: Ünite, 2000 tarihli yapı ile 2025 onaylı projenin aynı olup olmadığı sahada bakılacak.
A22: Atıksu türü | B22: Endüstriyel. Evsel hat da aynı tesiste arıtılıyor. | C22: Kimlik + aylık rapor B.1.2 ve B.1.3 | D22: Birlikte arıtımda evsel debiye bakılmaz. Standart Tablo 5.9’dur. Tablo 21 uygulanmaz.
A23: Arıtma | B23: Fiziksel, biyolojik, dezenfeksiyon. Dengeleme havuzu, klasik aktif çamur, klor ve bileşikleri. | C23: Kimlik belgesi | D23: B sınıfı tesis personel yükümlülüğü doğar.
A24: Kapasite | B24: 90 m³/gün kurulu | C24: Kimlik, proje formu | D24: İzleme sıklığı fiili debiye bağlıdır. Kurulu kapasite 51-200 bandındadır.
A25: Deşarj yeri | B25: Alıcı ortam: Nacarlı Deresi. Havza: Doğu Akdeniz. | C25: Kimlik ve proje formu | D25: Hassas su kütlesi veya sulama bağlantısı izin ekiyle teyit edilecek. Dosyada ilave N/P şartı yok.
... A29: Çevre görevlisi | B29: Asena Kübra Turhan, KBRÇEV. Sözleşme 18.08.2026. | C29: Aylık rapor ve iç tetkik | D29: Çevre görevlisi tesis sorumlusunun yerine geçmez.
A30: İşletme yetkilisi | B30: İrem Çakır | C30: Aylık rapor, iç tetkik imza
A31: Danışman firma | B31: KBRÇEV Çevre Danışmanlık ve Mühendislik Ltd. Şti. | C31: Aylık rapor, iç tetkik | D31: Proje onayını Bentos hazırlamış. İşletme danışmanlığı KBRÇEV’de.
A32: İç izleme beyanı | B32: 04.09.2026 iç tetkik: numune alınmamış. 24.09.2026 aylık rapor: rapor döneminde numune alınmış. | C32: İki rapor | D32: Analiz raporu bu sete dahil değil. Sonuç görülmeden uygunluk yazılmaz.
A33: Yağmur ve yıkama | B33: 6.1.3: endüstriyel yıkama suyu arıtılıyor. 6.1.4: yağmur ve yıkama suları ayrı sistemde toplanıp deşarj ediliyor. | C33: İç tetkik | D33: En kritik saha doğrulaması. Yıkama suyu yağmur hattıyla dereye gidiyorsa arıtılmamış deşarjdır.
A34: Yeraltı suyu | B34: Kuyu kullanımı var. DSİ belgesi konusunda bilgilendirme yapılmış. Dönemde yeraltı suyu numunesi alınmamış. | C34: Aylık B.1.7, iç tetkik 6.1.7 | D34: Belgenin kendisi dosyada yok.
A35: Hava / baca | B35: 03.07.2009 tarihli yönetmelik kapsamında baca bulunduğu yazılmış. İç izleme baca gazı ölçümü yok. Emisyon konulu izin yok. | C35: Aylık B.2, iç tetkik 6.4 ve 6.2 | D35: Baca envanteri çıkarılıp emisyon izni gerekip gerekmediği kapatılacak.
A36: Gürültü | B36: Ek-1 madde 7.9 gürültü izninden muaf tesisler arasında. 07.08.2026 tarihli 22579501-150/E.9446 veya E.944 uygunluk yazısı. | C36: Aylık B.4, iç tetkik 6.4 | D36: Sayı E.944 / E.9446 olarak iki raporda ayrışıyor. İmzalı yazı esas.
A37: Toprak | B37: Faaliyet, Toprak Kirliliği Kontrolü Yönetmeliği Ek-2 listesinde değil denmiş. Beyan formu yapılmamış. | C37: Aylık B.5, iç tetkik 6.5 | D37: Güncel Ek-2 listesi NACE ve mumlama faaliyetiyle bir kez daha karşılaştırılsın.
A38: BEKRA | B38: 29.04.2025, bildirim no 164505, seviye kapsam dışı. | C38: Aylık B.7, iç tetkik 6.9 | D38: Kimyasal veya depolama miktarı değişirse bildirim yenilenir.
A39: Kimyasallar | B39: Üretim veya ithalat yok, SEA beyanı yok. Yıkama ve mumlamada kullanılan kimyasallar için SDS istendiği yazılmış. | C39: Aylık B.6, iç tetkik 6.6 | D39: Hipoklorit, mum, varsa fungusit ve etilen SDS’si klasörde fiilen duruyor mu, bakılacak.
A40: Atıklar | B40: 15 01 01, 15 01 02, 15 01 06, 15 01 10*, 15 02 02*, 19 08 13*, 20 01 08, 20 01 26*, 20 01 34. | C40: Aylık B.3.1, iç tetkik 6.3.1 | D40: 19 08 01 ızgara ve 19 08 02 kum listede yok. Oluşuyorsa eklenecek.
A41: Atık sözleşmesi | B41: İç tetkikte sözleşme bulunmadığı yazıyor. | C41: İç tetkik 6.3.7 | D41: Tehlikeli atıklar için lisanslı firma sözleşmesi şart.
A42: Atık analizi | B42: Raporlama döneminde yapılmamış. | C42: Aylık B.3.3, iç tetkik 6.3.3 | D42: 19 08 13* kodu analizle doğrulanacak. Analizden önce tehlikesize çevrilmez.
A43: Atık yönetim planı | B43: E.14153800 sayılı üst yazı ile 03.11.2028’e kadar geçerli. | C43: Aylık rapor ve iç tetkik
A44: Atık beyanı | B44: 2025 yılı beyanı yapılmış. | C44: Aylık rapor sonuç | D44: 2026 yılı kayıtları ay ay tutulsun. Beyan Mart 2027’de.
...

Sheet Yapilacaklar
A1: YAPILACAK İŞLER
A2: Durum sütununu listeden seçin. İş bitince tamamlanma tarihini ve kanıt dosyasının adını yazın. Özet sayfasındaki sayaç buradan gelir.
A4: No | B4: Öncelik | C4: Süreç | D4: Konu | E4: Ne yapılacak | F4: Kaynak | G4: Sorumlu | H4: Hedef tarih | I4: Durum | J4: Tamamlanma | K4: Kanıt dosyası | L4: Not
A5: Y-01 | B5: Kritik | C5: Atıksu hattı | D5: Yıkama suyu nereye gidiyor? | E5: Yıkama, durulama, mumlama süzüntüsü ve zemin yıkama hatlarını uçtan uca yürüyün. Hepsi AAT girişinde birleşiyor mu, yağmur hattına veya dereye kaçan vana var mı, fotoğraf ve kroki ile dosyalayın. Kaçak hat varsa aynı gün AAT’ye alın ve bypass’ı kilitleyin. | F5: İç tetkik 6.1.3 ile 6.1.4 çelişkisi | G5: Danışman + işletme | H5: 46310 | I5: Açık | L5: Hat şeması görülmeden deşarj uygunluğu yazılmasın.
A6: Y-02 | B6: Kritik | C6: İç izleme | D6: Eylül 2026 analiz raporu | E6: Aylık raporda numune alındığı, iç tetkikte alınmadığı yazıyor. Analiz raporunu, numune tutanağını ve o günkü debiyi bulun. KOİ 150 mg/L, AKM 200 mg/L ve pH 6-9 ile kıyaslayın. Aşım varsa il müdürlüğüne bildirim ve on iş günü içindeki iki ek numune dosyada mı bakın. Rapor yoksa yetkili laboratuvarla 2 saatlik kompozit numuneyi bu hafta planlayın. | F6: 04.09 iç tetkik 6.1.7 ve 24.09 aylık B.1.6 | G6: Çevre görevlisi | H6: 46302 | I6: Açık | L6: Sonuç görülmeden ‘limitlere uygun’ cümlesi rapora yazılmayacak.
A7: Y-03 | B7: Kritik | C7: Personel | D7: Tesis sorumlusu ataması | E7: Kimlik belgesindeki tesis sorumlusu boş. Biyolojik arıtma ve 50-1000 m³/gün münferit sanayi tesisi B sınıfıdır. Tam zamanlı çevre mühendisi, ikincil veya ileri arıtmada en az üç yıl deneyim ve tesis sorumlusu belgesi aranır. Atama sonrası kimlik belgesi il müdürlüğünde güncellensin. | F7: Kimlik belgesi, 23.05.2019 tarihli tebliğ | G7: İşletme | H7: 46326 | I7: Açık | L7: KBRÇEV çevre görevlisi bu kadroyu karşılamaz.
A8: Y-04 | B8: Kritik | C8: Atık | D8: Sözleşme ve çamur analizi | E8: 15 01 10*, 15 02 02*, 19 08 13* ve 20 01 26* için lisanslı geri kazanım veya bertaraf sözleşmesi yapın. AAT çamurundan temsilî numune aldırın. Sonuç tehlikeliyse kod 19 08 13* kalır ve MOTAT zorunludur. Tehlikesiz çıkarsa 19 08 14’e geçin ve beyanı düzeltin. Geçici depolama sızdırmaz, etiketli ve yağmurdan ayrı olsun. | F8: İç tetkik 6.3.3 ve 6.3.7 | G8: Danışman + işletme | H8: 46326 | I8: Açık | L8: Analiz gelmeden kodu tehlikesize çevirmeyin.
A9: Y-05 | B9: Yüksek | C9: İzin | D9: Çevre izin çıktısı ve eki | E9: e-İzin’den atıksu deşarjı belge çıktısını ve ekini indirin. Ekteki debi, tablo, parametre, izleme sıklığı ve varsa ilave şart bu dosyadaki değerlerin önüne geçer. GFB 26.08.2027’de biter. Belge henüz oluşmamışsa GFB süresinde izin sürecini tamamlayın. | F9: GFB 3069574032.1.1 ve uygunluk yazısı | G9: Çevre görevlisi | H9: 46310 | I9: Açık | L9: Uygunluk yazısı ile beş yıllık belge aynı evrak değildir.
A10: Y-06 | B10: Yüksek | C10: Su temini | D10: DSİ yeraltı suyu belgesi | E10: Kuyu kullanılıyor ve belge dosyada yok. DSİ arama veya kullanma belgesini ya da tahsis yazısını isteyin. Yoksa başvuru başlatın. Kuyu sayacını okuyup SuDengesi sayfasına işleyin. | F10: Aylık B.1.7, iç tetkik 6.1.7 | G10: İşletme | H10: 46326 | I10: Açık | L10: Belge yokken kuyu debisini su dengesinden düşmeyin; ölçün ve ayrıca işaretleyin.
A11: Y-07 | B11: Yüksek | C11: Debi | D11: Günlük debi defteri | E11: Giriş ve deşarj debisini GunlukIsletme sayfasına her gün yazın. 90 m³/gün aşımı kapasite ihlalidir. Fiili debi sürekli 50 m³/gün ve altında kalırsa izleme dört aya ancak il müdürlüğünün yazısıyla iner. | F11: Kimlik kapasitesi 90 m³/gün | G11: Tesis işletmecisi | H11: 46310 | I11: Açık | L11: Su sayaçları (şebeke ve kuyu) ay sonunda SuDengesi’ne taşınsın.
A12: Y-08 | B12: Yüksek | C12: Sigorta | D12: Tehlikeli atık mali sorumluluk sigortası | E12: Poliçe 23.02.2027’de bitiyor. Poliçe PDF’sini dosyalayın. Ocak 2027’de yenileme teklifini alın. Teminat, tesisin tehlikeli atık kodlarını kapsasın. | F12: İç tetkik 6.3.6 | G12: İşletme | H12: 46402 | I12: Açık | L12: Poliçe numarası mevcut raporlarda yok.
A13: Y-09 | B13: Yüksek | C13: Kapasite | D13: Kapasite raporu yenileme | E13: TOBB kapasite raporu 03.03.2027’de bitiyor. Yenilenince günlük tonajı ÇED kapsam dışı kararı, Ek-1 madde 7.9 eşiği (100 ton/gün) ve KSTK eşiği ile yeniden karşılaştırın. | F13: 13.03.2025 / 150437 | G13: İşletme | H13: 46402 | I13: Açık | L13: Mumlama 26.880 ton/yıl. Günlük eşik, çalışma günü sayısına göre değişir.
A14: Y-10 | B14: Yüksek | C14: Personel sayısı | D14: 49 ile 60 çelişkisi | E14: SGK hizmet listesinden güncel çalışan sayısını alın. İç tetkikteki su verimliliği muafiyeti 50 kişinin altına bağlanmış; aynı rapor toplamı 60. Sayı 50 ve üzerindeyse Su Verimliliği Yönetmeliği Ek-2 yükümlülüğünü yeniden değerlendirin. | F14: Aylık rapor A bölümü ve iç tetkik 1 ve 6.13 | G14: Danışman | H14: 46326 | I14: Açık | L14: Muafiyet cümlesi personel netleşmeden tekrar yazılmasın.
A15: Y-11 | B15: Orta | C15: Dezenfeksiyon | D15: Klor dozu ve dere gözlemi | E15: Çıkışta pH ve serbest kloru günlük ölçün. Nacarlı Deresi mansabında renk, koku, köpük ve balık etkisini ziyarette kaydedin. Serbest klor yüksekse dozu düşürün. Tablo 5.9’da klor limiti yoktur; gerekçe dere canlılığıdır. | F15: Kimlik: klor ile dezenfeksiyon | G15: Tesis işletmecisi | H15: 46310 | I15: Açık | L15: Doz kaydı olmadan ‘dezenfeksiyon yapılıyor’ denmez.
A16: Y-12 | B16: Orta | C16: Kimyasal | D16: SDS klasörü ve BEKRA sınırı | E16: Hipoklorit, mum, varsa hasat sonrası fungusit ve etilen tüplerinin SDS’lerini, yıllık azami depolama miktarını ve dökülme setini klasöre koyun. Miktar veya madde değişirse 29.04.2025 / 164505 sayılı kapsam dışı bildirimini güncelleyin. | F16: Aylık B.6 ve B.7 | G16: İşletme | H16: 46326 | I16: Açık | L16: Mum ve fungusit çamur tehlikesini etkiler. Çamur analiz kapsamına yazılsın.
... A22: Y-18 | B22: Orta | C22: Atık beyanı | D22: 2026 yılı kütle kaydı | E22: 2025 beyanı yapılmış. 2026 için her sevkiyatın tarih, kod, miktar, firma ve MOTAT numarasını AtikTakip sayfasına işleyin. Beyan Mart 2027’de bu kayıttan çıkacak. | F22: Aylık rapor sonuç maddesi | G22: Çevre görevlisi | H22: 46461 | I22: Açık | L22: Ay sonu sıfır hareket bile ‘hareket yok’ diye işaretlensin.
A23: Y-19 | B23: Orta | C23: AAT atığı | D23: Izgara ve kum kodu | E23: Atık listesinde 19 08 01 ve 19 08 02 yok. Izgara ve kum oluşuyorsa kod, geçici depolama ve beyan kapsamına alın. Oluşmuyorsa bunun gerekçesini saha notuna yazın. | F23: Atık listesi | G23: Danışman | H23: 46341 | I23: Açık
A24: Y-20 | B24: Orta | C24: Bypass | D24: Vana kilidi | E24: Ham suyun dereye gidebildiği her vanayı bulun. Kilit, mühür veya kayıt dışı kullanım yasağını işletme defterine bağlayın. Ay içinde açıldıysa saatini ve gerekçesini GunlukIsletme’ye yazın. | F24: Deşarj yasağı, SKKY seyreltme ve kaçak deşarj hükümleri | G24: Tesis işletmecisi | H24: 46310 | I24: Açık | L24: İç tetkikte kaza yok denmesi, vananın kilitli olduğunu göstermez.
A25: Y-21 | B25: Düşük | C25: Eğitim | D25: 24.09.2026 katılım formu | E25: Aylık raporda çevre mevzuatı, genel atık ve sıfır atık eğitiminin 24.09.2026’da verildiği yazıyor. Yoklama ve konu başlığını dosyalayın. İç tetkik aynı eğitimi henüz verilecek diye yazmıştı. | F25: Aylık rapor E.1 | G25: Çevre görevlisi | H25: 46310 | I25: Açık
A26: Y-22 | B26: Düşük | C26: Sözleşme dosyası | D26: Danışmanlık faturası ile sözleşme ayrılsın | E26: Aylık raporda son fatura yerine 18.08.2026 sözleşme tarihi yazılmış. Sözleşme ve her ayın fatura numarası ayrı izlensin. | F26: Aylık rapor A bölümü | G26: KBRÇEV / işletme | H26: 46326 | I26: Açık

Sheet BelgeTakvimi
A1: BELGE TAKVİMİ
A2: Bitiş tarihi yazılı satırlarda kalan gün ve durum kendiliğinden hesaplanır. Süresiz belgelerde bitiş boş bırakıldı.
A4: Kod | B4: Belge | C4: Sayı / tarih | D4: Başlangıç | E4: Bitiş | F4: Kalan gün | G4: Durum | H4: Dosyada var mı | I4: Ne zaman yenilenir | J4: Not
A5: B-01 | B5: ÇED kapsam dışı kararı | C5: 24.02.2025 / E-23645791-220.03-11844865 | F5: =IF(E5="","",E5-TODAY()) | G5: =IF(E5="","Süresiz / olaya bağlı",IF(E5<TODAY(),"SÜRESİ GEÇTİ",IF(E5-TODAY()<=60,"60 GÜN İÇİNDE","GEÇERLİ"))) | H5: Evet | I5: Kapasite veya proses değişince | J5: Yıkama, sarartma, mumlama, ambalajlama ve soğuk hava için.
A6: B-02 | B6: AAT proje onayı | C6: 15.08.2025 / E-27907008-100-13239842 | D6: 45884 | F6: =IF(E6="","",E6-TODAY()) | G6: =IF(E6="","Süresiz / olaya bağlı",IF(E6<TODAY(),"SÜRESİ GEÇTİ",IF(E6-TODAY()<=60,"60 GÜN İÇİNDE","GEÇERLİ"))) | H6: Evet | I6: Revizyon veya kapasite artışı | J6: Form no AAT03608. İç tetkikteki 13239847 sayısı kullanılmasın.
A7: B-03 | B7: AAT kimlik belgesi | C7: 10.09.2025 / 33.25-3069574032-344 | D7: 45910 | F7: =IF(E7="","",E7-TODAY()) | G7: =IF(E7="","Süresiz / olaya bağlı",IF(E7<TODAY(),"SÜRESİ GEÇTİ",IF(E7-TODAY()<=60,"60 GÜN İÇİNDE","GEÇERLİ"))) | H7: Evet | I7: Tesis sorumlusu, koordinat veya kapasite değişince | J7: Tesis sorumlusu boş. Üst yazı E.13621421.
A8: B-04 | B8: Atıksu deşarjı GFB | C8: 26.08.2026 / 58003700-150/E.5093 / 3069574032.1.1 | D8: 46260 | E8: 46625 | F8: =IF(E8="","",E8-TODAY()) | G8: =IF(E8="","Süresiz / olaya bağlı",IF(E8<TODAY(),"SÜRESİ GEÇTİ",IF(E8-TODAY()<=60,"60 GÜN İÇİNDE","GEÇERLİ"))) | H8: Evet | I8: 26.08.2027’den önce çevre izin belgesi | J8: Konu yalnız atıksu deşarjı.
A9: B-05 | B9: İl müdürlüğü uygunluk yazısı | C9: 07.08.2026 / E.944 veya E.9446 | D9: 46241 | F9: =IF(E9="","",E9-TODAY()) | G9: =IF(E9="","Süresiz / olaya bağlı",IF(E9<TODAY(),"SÜRESİ GEÇTİ",IF(E9-TODAY()<=60,"60 GÜN İÇİNDE","GEÇERLİ"))) | H9: Teyit | I9: e-İzin belge çıktısı ile birlikte | J9: Başvuru 05.06.2026 / 700227. Sayı asıl yazıdan doğrulanacak.
A10: B-06 | B10: Çevre izin belgesi (5 yıl) | C10: Dosyada yok | F10: =IF(E10="","",E10-TODAY()) | G10: =IF(E10="","Süresiz / olaya bağlı",IF(E10<TODAY(),"SÜRESİ GEÇTİ",IF(E10-TODAY()<=60,"60 GÜN İÇİNDE","GEÇERLİ"))) | H10: Hayır | I10: GFB bitmeden | J10: Çıktı ve ek geldiğinde B-04’ün yerine asıl belge olur. Ek limitleri Excel’e işlenecek.
A11: B-07 | B11: Gürültü muafiyet / uygunluk | C11: 07.08.2026 / 22579501-150/E.944 veya E.9446 | D11: 46241 | F11: =IF(E11="","",E11-TODAY()) | G11: =IF(E11="","Süresiz / olaya bağlı",IF(E11<TODAY(),"SÜRESİ GEÇTİ",IF(E11-TODAY()<=60,"60 GÜN İÇİNDE","GEÇERLİ"))) | H11: Teyit | I11: Kapasite veya ekipman değişince | J11: Ek-1 7.9 gürültü izninden muaf tesisler arasında değerlendirilmiş.
A12: B-08 | B12: Kapasite raporu | C12: 13.03.2025 / 150437 / TOBB | D12: 45729 | E12: 46449 | F12: =IF(E12="","",E12-TODAY()) | G12: =IF(E12="","Süresiz / olaya bağlı",IF(E12<TODAY(),"SÜRESİ GEÇTİ",IF(E12-TODAY()<=60,"60 GÜN İÇİNDE","GEÇERLİ"))) | H12: Evet | I12: 03.03.2027 öncesi | J12: Ambalaj 1.152 ton/yıl, mumlama ve sarartma 26.880 ton/yıl.
A13: B-09 | B13: Tehlikeli atık mali sorumluluk sigortası | C13: 23.02.2026 – 23.02.2027 | D13: 46076 | E13: 46441 | F13: =IF(E13="","",E13-TODAY()) | G13: =IF(E13="","Süresiz / olaya bağlı",IF(E13<TODAY(),"SÜRESİ GEÇTİ",IF(E13-TODAY()<=60,"60 GÜN İÇİNDE","GEÇERLİ"))) | H13: Teyit | I13: 23.02.2027 öncesi | J13: Poliçe numarası raporda yok. PDF dosyalansın.
A14: B-10 | B14: Atık yönetim planı | C14: E.14153800 / 03.11.2028’e kadar | E14: 47060 | F14: =IF(E14="","",E14-TODAY()) | G14: =IF(E14="","Süresiz / olaya bağlı",IF(E14<TODAY(),"SÜRESİ GEÇTİ",IF(E14-TODAY()<=60,"60 GÜN İÇİNDE","GEÇERLİ"))) | H14: Evet | I14: 03.11.2028 öncesi | J14: Başlangıç tarihi raporda yok.
A15: B-11 | B15: 2025 atık beyanı | C15: Yapılmış deniyor | F15: =IF(E15="","",E15-TODAY()) | G15: =IF(E15="","Süresiz / olaya bağlı",IF(E15<TODAY(),"SÜRESİ GEÇTİ",IF(E15-TODAY()<=60,"60 GÜN İÇİNDE","GEÇERLİ"))) | H15: Teyit | I15: 2026 beyanı Mart 2027 | J15: Beyan çıktısı PDF olarak dosyada ayrıca durmalı.
A16: B-12 | B16: Tehlikeli atık bertaraf sözleşmeleri | C16: İç tetkik: sözleşme yok | F16: =IF(E16="","",E16-TODAY()) | G16: =IF(E16="","Süresiz / olaya bağlı",IF(E16<TODAY(),"SÜRESİ GEÇTİ",IF(E16-TODAY()<=60,"60 GÜN İÇİNDE","GEÇERLİ"))) | H16: Hayır | I16: Hemen | J16: 15 01 10*, 15 02 02*, 19 08 13*, 20 01 26*.
A17: B-13 | B17: Çamur karakterizasyon analizi | C17: Dönemde yapılmamış | F17: =IF(E17="","",E17-TODAY()) | G17: =IF(E17="","Süresiz / olaya bağlı",IF(E17<TODAY(),"SÜRESİ GEÇTİ",IF(E17-TODAY()<=60,"60 GÜN İÇİNDE","GEÇERLİ"))) | H17: Hayır | I17: Sözleşme ile birlikte | J17: 19 08 13* kodunu doğrular veya 19 08 14’e çevirir.
A18: B-14 | B18: BEKRA bildirimi | C18: 29.04.2025 / 164505 / seviye kapsam dışı | D18: 45776 | F18: =IF(E18="","",E18-TODAY()) | G18: =IF(E18="","Süresiz / olaya bağlı",IF(E18<TODAY(),"SÜRESİ GEÇTİ",IF(E18-TODAY()<=60,"60 GÜN İÇİNDE","GEÇERLİ"))) | H18: Evet | I18: Kimyasal miktarı değişince
A19: B-15 | B19: Sıfır atık temel seviye belgesi | C19: 06.05.2025 / T5/33/C/20/368 | D19: 45783 | F19: =IF(E19="","",E19-TODAY()) | G19: =IF(E19="","Süresiz / olaya bağlı",IF(E19<TODAY(),"SÜRESİ GEÇTİ",IF(E19-TODAY()<=60,"60 GÜN İÇİNDE","GEÇERLİ"))) | H19: Evet | I19: Sistem bozulursa veya seviye yükselirse | J19: 3’lü kumbara kurulmuş.
A20: B-16 | B20: DSİ yeraltı suyu kullanım belgesi | C20: Dosyada yok, kullanım var | F20: =IF(E20="","",E20-TODAY()) | G20: =IF(E20="","Süresiz / olaya bağlı",IF(E20<TODAY(),"SÜRESİ GEÇTİ",IF(E20-TODAY()<=60,"60 GÜN İÇİNDE","GEÇERLİ"))) | H20: Hayır | I20: Başvuru veya belge derhal | J20: Aylık raporda cezai sonuç hakkında bilgilendirme yapılmış.
A21: B-17 | B21: Çevre danışmanlık sözleşmesi | C21: 18.08.2026 / KBRÇEV | D21: 46252 | F21: =IF(E21="","",E21-TODAY()) | G21: =IF(E21="","Süresiz / olaya bağlı",IF(E21<TODAY(),"SÜRESİ GEÇTİ",IF(E21-TODAY()<=60,"60 GÜN İÇİNDE","GEÇERLİ"))) | H21: Evet | I21: Sözleşme süresine göre | J21: Bitiş tarihi raporda yazmıyor. Sözleşmeden işlensin.
A22: B-18 | B22: Tesis sorumlusu belgesi | C22: Yok | F22: =IF(E22="","",E22-TODAY()) | G22: =IF(E22="","Süresiz / olaya bağlı",IF(E22<TODAY(),"SÜRESİ GEÇTİ",IF(E22-TODAY()<=60,"60 GÜN İÇİNDE","GEÇERLİ"))) | H22: Hayır | I22: Atama ile birlikte | J22: 5 yıl geçerli belge. Kimliğe işlenecek.
A23: B-19 | B23: İç izleme analiz raporu (Eylül 2026) | C23: Alındı deniyor, rapor sette yok | F23: =IF(E23="","",E23-TODAY()) | G23: =IF(E23="","Süresiz / olaya bağlı",IF(E23<TODAY(),"SÜRESİ GEÇTİ",IF(E23-TODAY()<=60,"60 GÜN İÇİNDE","GEÇERLİ"))) | H23: Hayır | I23: Hemen bulun veya yeniden alın | J23: Sonraki kampanya iki ay sonra.
A24: B-20 | B24: Eğitim katılım formu | C24: 24.09.2026’da verildi deniyor | D24: 46289 | F24: =IF(E24="","",E24-TODAY()) | G24: =IF(E24="","Süresiz / olaya bağlı",IF(E24<TODAY(),"SÜRESİ GEÇTİ",IF(E24-TODAY()<=60,"60 GÜN İÇİNDE","GEÇERLİ"))) | H24: Teyit | I24: Yılda en az bir kez dosyalansın | J24: Çevre mevzuatı, genel atık, sıfır atık.
A25: B-21 | B25: Toprak kirliliği ön bilgi formu | C25: Ek-2 dışı denmiş, form yok | F25: =IF(E25="","",E25-TODAY()) | G25: =IF(E25="","Süresiz / olaya bağlı",IF(E25<TODAY(),"SÜRESİ GEÇTİ",IF(E25-TODAY()<=60,"60 GÜN İÇİNDE","GEÇERLİ"))) | H25: Muaf denmiş | I25: Ek-2 listesi değişirse | J25: Güncel listeyle bir kez daha doğrulansın.
A26: B-22 | B26: Emisyon ölçüm / izin dosyası | C26: Baca var deniyor, ölçüm yok | F26: =IF(E26="","",E26-TODAY()) | G26: =IF(E26="","Süresiz / olaya bağlı",IF(E26<TODAY(),"SÜRESİ GEÇTİ",IF(E26-TODAY()<=60,"60 GÜN İÇİNDE","GEÇERLİ"))) | H26: Hayır | I26: Baca envanterinden sonra | J26: Emisyon izni gerekmediği yazıyla kapatılacak ya da başvuru açılacak.

Sheet AylikKontrol
A1: AYLIK SAHA VE DOSYA KONTROLÜ
A2: Her ziyarette hücreye Uygun, Uygun değil, Gözlenmedi veya Kapsam dışı yazın. Uygun değil olan satır Uygunsuzluk sayfasına işlenir.
A4: Grup | B4: Kontrol | C4: Eki26 | D4: Kas26 | E4: Ara26 | F4: Oca27 | G4: Şub27 | H4: Mar27 | I4: Nis27 | J4: May27 | K4: Haz27 | L4: Tem27 | M4: Ağu27 | N4: Eyl27 | O4: Not
A5: Hat | B5: Meyve ve sebze yıkama suyu AAT girişine bağlı
A6: Hat | B6: Durulama suyu AAT girişine bağlı
A7: Hat | B7: Mumlama süzüntüsü ve zemin yıkama AAT’ye bağlı
A8: Hat | B8: Sosyal tesis evsel suyu AAT’ye bağlı
A9: Hat | B9: Yağmur suyu AAT’ye ve proses hattına karışmıyor
A10: Hat | B10: Temiz su, kuyu suyu veya soğutma suyu ile seyreltme yok
A11: Hat | B11: Bypass vanası kapalı, kilitli veya kayıt altında
A12: Hat | B12: Dereye giden kaçak hortum veya ikinci deşarj ucu yok
A13: Ünite | B13: Izgara temiz, tutulan atık sahada birikmiyor
A14: Ünite | B14: Kum tutucu çalışıyor
A15: Ünite | B15: Dengeleme havuzu seviye ve karıştırması normal, taşma yok
A16: Ünite | B16: Havalandırmada çözünmüş oksijen, renk ve koku normal
... A41: Diğer | B41: Tesis sorumlusu belgesi ve kimlik güncel
A43: Uygun = şart sağlandı. Uygun değil = uygunsuzluk kaydı açın. Gözlenmedi = bu ziyarette bakılamadı, sonraki ziyarette kapanır. Kapsam dışı = tesiste yok, notuna gerekçe yazın.

Sheet IcIzleme
A1: İÇ İZLEME — SKKY TABLO 5.9
A2: Yasal kıyas 2 saatlik kompozittir. Limitler: KOİ 150 mg/L, AKM 200 mg/L, pH 6-9. pH’de yüzde 20 payı yoktur. KOİ ve AKM anlık numunede limitin yüzde 20 fazlası yaptırıma esas değerlendirilir; iç izlemeyi anlık numuneyle kapatmayın. Aşımda il müdürlüğüne bildirim ve on iş günü içinde iki ek numune. Üç sonucun ortalaması yazılır.
A4: No | B4: Plan | C4: Numune tarihi | D4: Numune türü | E4: Laboratuvar | F4: Rapor no | G4: Debi m³/gün | H4: KOİ | I4: KOİ limit | J4: KOİ sonuç | K4: AKM | L4: AKM limit | M4: AKM sonuç | N4: pH | O4: pH alt | P4: pH üst | Q4: pH sonuç | R4: Genel sonuç | S4: Bildirim gerekli | T4: Ek numune tarihi | U4: Üçlü ortalama uygun mu | V4: Dosya | W4: Not
A5: 1 | B5: Eylül 2026 | D5: 2 saatlik kompozit | I5: 150 | J5: =IF(H5="","",IF(H5<=I5,"UYGUN","AŞIM")) | L5: 200 | M5: =IF(K5="","",IF(K5<=L5,"UYGUN","AŞIM")) | O5: 6 | P5: 9 | Q5: =IF(N5="","",IF(AND(N5>=O5,N5<=P5),"UYGUN","AŞIM")) | R5: =IF(COUNT(H5,K5,N5)<3,"EKSİK",IF(OR(J5="AŞIM",M5="AŞIM",Q5="AŞIM"),"AŞIM","UYGUN")) | S5: =IF(R5="AŞIM","Evet",IF(R5="UYGUN","Hayır","")) | W5: Alındığı beyan edildi, rapor dosyada yok. Sonucu bu satıra işleyin.
A6: 2 | B6: Kasım 2026 | D6: 2 saatlik kompozit | I6: 150 | J6: =IF(H6="","",IF(H6<=I6,"UYGUN","AŞIM")) | L6: 200 | M6: =IF(K6="","",IF(K6<=L6,"UYGUN","AŞIM")) | O6: 6 | P6: 9 | Q6: =IF(N6="","",IF(AND(N6>=O6,N6<=P6),"UYGUN","AŞIM")) | R6: =IF(COUNT(H6,K6,N6)<3,"EKSİK",IF(OR(J6="AŞIM",M6="AŞIM",Q6="AŞIM"),"AŞIM","UYGUN")) | S6: =IF(R6="AŞIM","Evet",IF(R6="UYGUN","Hayır","")) | W6: Eylül numunesinden iki ay sonra. Tarih netleşince yazın.
A7: 3 | B7: Ocak 2027 | D7: 2 saatlik kompozit | I7: 150 | J7: =IF(H7="","",IF(H7<=I7,"UYGUN","AŞIM")) | L7: 200 | M7: =IF(K7="","",IF(K7<=L7,"UYGUN","AŞIM")) | O7: 6 | P7: 9 | Q7: =IF(N7="","",IF(AND(N7>=O7,N7<=P7),"UYGUN","AŞIM")) | R7: =IF(COUNT(H7,K7,N7)<3,"EKSİK",IF(OR(J7="AŞIM",M7="AŞIM",Q7="AŞIM"),"AŞIM","UYGUN")) | S7: =IF(R7="AŞIM","Evet",IF(R7="UYGUN","Hayır",""))
A8: 4 | B8: Mart 2027 | D8: 2 saatlik kompozit | I8: 150 | J8: =IF(H8="","",IF(H8<=I8,"UYGUN","AŞIM")) | L8: 200 | M8: =IF(K8="","",IF(K8<=L8,"UYGUN","AŞIM")) | O8: 6 | P8: 9 | Q8: =IF(N8="","",IF(AND(N8>=O8,N8<=P8),"UYGUN","AŞIM")) | R8: =IF(COUNT(H8,K8,N8)<3,"EKSİK",IF(OR(J8="AŞIM",M8="AŞIM",Q8="AŞIM"),"AŞIM","UYGUN")) | S8: =IF(R8="AŞIM","Evet",IF(R8="UYGUN","Hayır",""))
A9: 5 | B9: Mayıs 2027 | D9: 2 saatlik kompozit | I9: 150 | J9: =IF(H9="","",IF(H9<=I9,"UYGUN","AŞIM")) | L9: 200 | M9: =IF(K9="","",IF(K9<=L9,"UYGUN","AŞIM")) | O9: 6 | P9: 9 | Q9: =IF(N9="","",IF(AND(N9>=O9,N9<=P9),"UYGUN","AŞIM")) | R9: =IF(COUNT(H9,K9,N9)<3,"EKSİK",IF(OR(J9="AŞIM",M9="AŞIM",Q9="AŞIM"),"AŞIM","UYGUN")) | S9: =IF(R9="AŞIM","Evet",IF(R9="UYGUN","Hayır",""))
A10: 6 | B10: Temmuz 2027 | D10: 2 saatlik kompozit | I10: 150 | J10: =IF(H10="","",IF(H10<=I10,"UYGUN","AŞIM")) | L10: 200 | M10: =IF(K10="","",IF(K10<=L10,"UYGUN","AŞIM")) | O10: 6 | P10: 9 | Q10: =IF(N10="","",IF(AND(N10>=O10,N10<=P10),"UYGUN","AŞIM")) | R10: =IF(COUNT(H10,K10,N10)<3,"EKSİK",IF(OR(J10="AŞIM",M10="AŞIM",Q10="AŞIM"),"AŞIM","UYGUN")) | S10: =IF(R10="AŞIM","Evet",IF(R10="UYGUN","Hayır",""))
A11: 7 | B11: Eylül 2027 | D11: 2 saatlik kompozit | I11: 150 | J11: =IF(H11="","",IF(H11<=I11,"UYGUN","AŞIM")) | L11: 200 | M11: =IF(K11="","",IF(K11<=L11,"UYGUN","AŞIM")) | O11: 6 | P11: 9 | Q11: =IF(N11="","",IF(AND(N11>=O11,N11<=P11),"UYGUN","AŞIM")) | R11: =IF(COUNT(H11,K11,N11)<3,"EKSİK",IF(OR(J11="AŞIM",M11="AŞIM",Q11="AŞIM"),"AŞIM","UYGUN")) | S11: =IF(R11="AŞIM","Evet",IF(R11="UYGUN","Hayır","")) | W11: GFB 26.08.2027’de biter. İzin eki farklı sıklık verirse takvimi eke göre değiştirin.
A12: E-1 | B12: Ek numune | D12: 2 saatlik kompozit | I12: 150 | J12: =IF(H12="","",IF(H12<=I12,"UYGUN","AŞIM")) | L12: 200 | M12: =IF(K12="","",IF(K12<=L12,"UYGUN","AŞIM")) | O12: 6 | P12: 9 | Q12: =IF(N12="","",IF(AND(N12>=O12,N12<=P12),"UYGUN","AŞIM")) | R12: =IF(COUNT(H12,K12,N12)<3,"",IF(OR(J12="AŞIM",M12="AŞIM",Q12="AŞIM"),"AŞIM","UYGUN")) | S12: =IF(R12="AŞIM","Evet",IF(R12="UYGUN","Hayır","")) | W12: Limit aşımından sonraki on iş günü içinde alınan ek numune.
A13: E-2 | B13: Ek numune | D13: 2 saatlik kompozit | I13: 150 | J13: =IF(H13="","",IF(H13<=I13,"UYGUN","AŞIM")) | L13: 200 | M13: =IF(K13="","",IF(K13<=L13,"UYGUN","AŞIM")) | O13: 6 | P13: 9 | Q13: =IF(N13="","",IF(AND(N13>=O13,N13<=P13),"UYGUN","AŞIM")) | R13: =IF(COUNT(H13,K13,N13)<3,"",IF(OR(J13="AŞIM",M13="AŞIM",Q13="AŞIM"),"AŞIM","UYGUN")) | S13: =IF(R13="AŞIM","Evet",IF(R13="UYGUN","Hayır","")) | W13: Limit aşımından sonraki on iş günü içinde alınan ek numune.
A14: E-3 | B14: Ek numune | D14: 2 saatlik kompozit | I14: 150 | J14: =IF(H14="","",IF(H14<=I14,"UYGUN","AŞIM")) | L14: 200 | M14: =IF(K14="","",IF(K14<=L14,"UYGUN","AŞIM")) | O14: 6 | P14: 9 | Q14: =IF(N14="","",IF(AND(N14>=O14,N14<=P14),"UYGUN","AŞIM")) | R14: =IF(COUNT(H14,K14,N14)<3,"",IF(OR(J14="AŞIM",M14="AŞIM",Q14="AŞIM"),"AŞIM","UYGUN")) | S14: =IF(R14="AŞIM","Evet",IF(R14="UYGUN","Hayır","")) | W14: Limit aşımından sonraki on iş günü içinde alınan ek numune.
A15: E-4 | B15: Ek numune | D15: 2 saatlik kompozit | I15: 150 | J15: =IF(H15="","",IF(H15<=I15,"UYGUN","AŞIM")) | L15: 200 | M15: =IF(K15="","",IF(K15<=L15,"UYGUN","AŞIM")) | O15: 6 | P15: 9 | Q15: =IF(N15="","",IF(AND(N15>=O15,N15<=P15),"UYGUN","AŞIM")) | R15: =IF(COUNT(H15,K15,N15)<3,"",IF(OR(J15="AŞIM",M15="AŞIM",Q15="AŞIM"),"AŞIM","UYGUN")) | S15: =IF(R15="AŞIM","Evet",IF(R15="UYGUN","Hayır","")) | W15: Limit aşımından sonraki on iş günü içinde alınan ek numune.
A16: E-5 | B16: Ek numune | D16: 2 saatlik kompozit | I16: 150 | J16: =IF(H16="","",IF(H16<=I16,"UYGUN","AŞIM")) | L16: 200 | M16: =IF(K16="","",IF(K16<=L16,"UYGUN","AŞIM")) | O16: 6 | P16: 9 | Q16: =IF(N16="","",IF(AND(N16>=O16,N16<=P16),"UYGUN","AŞIM")) | R16: =IF(COUNT(H16,K16,N16)<3,"",IF(OR(J16="AŞIM",M16="AŞIM",Q16="AŞIM"),"AŞIM","UYGUN")) | S16: =IF(R16="AŞIM","Evet",IF(R16="UYGUN","Hayır","")) | W16: Limit aşımından sonraki on iş günü içinde alınan ek numune.
A17: E-6 | B17: Ek numune | D17: 2 saatlik kompozit | I17: 150 | J17: =IF(H17="","",IF(H17<=I17,"UYGUN","AŞIM")) | L17: 200 | M17: =IF(K17="","",IF(K17<=L17,"UYGUN","AŞIM")) | O17: 6 | P17: 9 | Q17: =IF(N17="","",IF(AND(N17>=O17,N17<=P17),"UYGUN","AŞIM")) | R17: =IF(COUNT(H17,K17,N17)<3,"",IF(OR(J17="AŞIM",M17="AŞIM",Q17="AŞIM"),"AŞIM","UYGUN")) | S17: =IF(R17="AŞIM","Evet",IF(R17="UYGUN","Hayır","")) | W17: Limit aşımından sonraki on iş günü içinde alınan ek numune.
A19: Laboratuvarın çevre ölçüm ve analiz yeterliği ile numune alma yetkisi olsun. İzin ve denetime esas numune il müdürlüğü gözetiminde alınır. İç izleme numunesi de yetkili laboratuvar tarafından alınır. Kayıt beş yıl saklanır.

Sheet GunlukIsletme
A1: GÜNLÜK İŞLETME DEFTERİ
A2: Tesis sorumlusu veya işletmeci her gün doldurur. Beş yıl saklanır. Bypass Evet ise aynı satıra gerekçe yazın ve Uygunsuzluk kaydı açın.
A4: Tarih | B4: Giriş m³ | C4: Şebeke sayaç | D4: Kuyu sayaç | E4: Çıkış / deşarj m³ | F4: Giriş pH | G4: Havalandırma ÇO mg/L | H4: Çıkış pH | I4: Çıkış sıcaklık °C | J4: Serbest klor mg/L | K4: Klor tüketimi | L4: Çamur çekimi m³ | M4: Bypass | N4: Dere gözlemi | O4: Arıza ve müdahale | P4: Kaydeden

Sheet SuDengesi
A1: AYLIK SU DENGESİ
A2: Şebeke ve kuyu sayaç farkları ile AAT giriş ve deşarj toplamını aynı aya yazın. Fark, ürün nemi, buharlaşma, sulama veya ölçülmeyen kaçak olabilir. Farkı gerekçesiz bırakmayın.
A4: Ay | B4: Şebeke m³ | C4: Kuyu m³ | D4: Toplam temin | E4: Evsel tahmin m³ | F4: Proses / yıkama m³ | G4: AAT giriş m³ | H4: Deşarj m³ | I4: Temin - deşarj farkı | J4: 90 m³ aşan gün sayısı | K4: Kuyu belgesi var mı | L4: Not
A5: Ekim 2026 | D5: =IF(COUNT(B5,C5)=0,"",N(B5)+N(C5)) | I5: =IF(OR(D5="",H5=""),"",D5-H5)
A6: Kasım 2026 | D6: =IF(COUNT(B6,C6)=0,"",N(B6)+N(C6)) | I6: =IF(OR(D6="",H6=""),"",D6-H6)
A7: Aralık 2026 | D7: =IF(COUNT(B7,C7)=0,"",N(B7)+N(C7)) | I7: =IF(OR(D7="",H7=""),"",D7-H7)
A8: Ocak 2027 | D8: =IF(COUNT(B8,C8)=0,"",N(B8)+N(C8)) | I8: =IF(OR(D8="",H8=""),"",D8-H8)
A9: Şubat 2027 | D9: =IF(COUNT(B9,C9)=0,"",N(B9)+N(C9)) | I9: =IF(OR(D9="",H9=""),"",D9-H9)
A10: Mart 2027 | D10: =IF(COUNT(B10,C10)=0,"",N(B10)+N(C10)) | I10: =IF(OR(D10="",H10=""),"",D10-H10)
A11: Nisan 2027 | D11: =IF(COUNT(B11,C11)=0,"",N(B11)+N(C11)) | I11: =IF(OR(D11="",H11=""),"",D11-H11)
A12: Mayıs 2027 | D12: =IF(COUNT(B12,C12)=0,"",N(B12)+N(C12)) | I12: =IF(OR(D12="",H12=""),"",D12-H12)
A13: Haziran 2027 | D13: =IF(COUNT(B13,C13)=0,"",N(B13)+N(C13)) | I13: =IF(OR(D13="",H13=""),"",D13-H13)
A14: Temmuz 2027 | D14: =IF(COUNT(B14,C14)=0,"",N(B14)+N(C14)) | I14: =IF(OR(D14="",H14=""),"",D14-H14)
A15: Ağustos 2027 | D15: =IF(COUNT(B15,C15)=0,"",N(B15)+N(C15)) | I15: =IF(OR(D15="",H15=""),"",D15-H15)
A16: Eylül 2027 | D16: =IF(COUNT(B16,C16)=0,"",N(B16)+N(C16)) | I16: =IF(OR(D16="",H16=""),"",D16-H16)
A17: TOPLAM | B17: =SUM(B5:B16) | C17: =SUM(C5:C16) | E17: =SUM(E5:E16) | F17: =SUM(F5:F16) | G17: =SUM(G5:G16) | H17: =SUM(H5:H16) | J17: =SUM(J5:J16)
A19: Evsel tahmin, personel sayısı ve vardiya tüketiminden hesaplanır. Proses sütunu yıkama ve mumlama reçetesinden gelir. İkisi ölçülmüyorsa boş bırakın, uydurmayın.

Sheet AtikTakip
A1: ATIK KODLARI VE SEVKİYAT
A2: Üst tablo dosyada yazılı kodlardır. Alt tabloya her sevkiyatı işleyin. 2026 beyanı bu kayıttan çıkacak.
A4: Kod | B4: Tanım | C4: Tehlikeli | D4: Sözleşme | E4: Analiz | F4: Geçici depolama notu
A5: 15 01 01 | B5: Kâğıt ve karton ambalaj | C5: Hayır | D5: Yok / yapılacak | E5: Gerekmez | F5: Sıfır atık kumbarası ile karışmasın
A6: 15 01 02 | B6: Plastik ambalaj | C6: Hayır | D6: Yok / yapılacak | E6: Gerekmez
A7: 15 01 06 | B7: Karışık ambalaj | C7: Hayır | D7: Yok / yapılacak | E7: Gerekmez | F7: Mümkünse kaynağında ayrılın
A8: 15 01 10* | B8: Tehlikeli madde kalıntılı ambalaj | C8: Evet | D8: Yok | E8: Gerekirse | F8: Ayrı, kapalı, etiketi kodu taşısın
A9: 15 02 02* | B9: Tehlikeli madde ile kirlenmiş emici, filtre, bez | C9: Evet | D9: Yok | E9: Gerekirse | F9: Açıkta bekletilmesin
A10: 19 08 13* | B10: Endüstriyel atıksu arıtma çamuru, tehlikeli | C10: Evet, beyan böyle | D10: Yok | E10: Yok, yaptırılacak | F10: Analiz 19 08 14 çıkarırsa kod ve sözleşme değişir
A11: 20 01 08 | B11: Mutfak ve kantin, biyolojik olarak bozunabilir | C11: Hayır | D11: Yok / yapılacak | E11: Gerekmez
A12: 20 01 26* | B12: 20 01 25 dışındaki sıvı ve katı yağlar | C12: Evet | D12: Yok | E12: Gerekirse | F12: Mum kaynaklı yağ bu koda gidebilir
A13: 20 01 34 | B13: 20 01 33 dışındaki pil ve akümülatör | C13: Hayır | D13: Yok / yapılacak | E13: Gerekmez
A14: 19 08 01 | B14: Izgara atığı | C14: Listede yok | D14: Oluşuyorsa yapılacak | E14: Oluşuma göre | F14: Sahada oluşup oluşmadığı Y-19 ile kapanacak
A15: 19 08 02 | B15: Kum tutucu atığı | C15: Listede yok | D15: Oluşuyorsa yapılacak | E15: Oluşuma göre | F15: Sahada oluşup oluşmadığı Y-19 ile kapanacak
A18: SEVKİYAT KAYDI
A19: Tarih | B19: Kod | C19: Miktar kg | D19: Firma | E19: Lisans no | F19: Araç plaka | G19: MOTAT no | H19: Fiş no | I19: Tehlikeli mi | J19: Sözleşme tarihi | K19: Teslim alan | L19: Not
A62: Ay içinde sevkiyat yoksa bir satıra ay adı ve ‘hareket yok’ yazın. Böylece beyan döneminde boşluk tartışması olmaz.

Sheet Uygunsuzluk
A1: UYGUNSUZLUK VE DÜZELTİCİ FAALİYET
A2: Aylık kontrolde Uygun değil işaretlenen her satır, limit aşımı, bypass, şikayet ve kaza buraya yazılır. Kök neden yazılmadan kapatmayın.
A4: No | B4: Tarih | C4: Kaynak | D4: Tanım | E4: Kök neden | F4: Düzeltme | G4: Sorumlu | H4: Hedef | I4: Durum | J4: Kapanış tarihi
A5: U-01 | B5: 46295 | C5: Belge incelemesi | D5: Yıkama suyunun AAT’ye mi yoksa ayrı hatta mı gittiği iki raporda çelişkili. | E5: Henüz sahada doğrulanmadı. | F5: Hat yürüyüşü, kroki, gerekirse bağlantı düzeltmesi. Y-01. | G5: Danışman + işletme | H5: 46310 | I5: Açık
A6: U-02 | B6: 46295 | C6: Belge incelemesi | D6: İç izleme alınmış deniyor, analiz raporu dosyada yok. | E6: Rapor arşive girmemiş veya numune henüz oluşmamış. | F6: Raporu bul veya yeniden numune al. Y-02. | G6: Çevre görevlisi | H6: 46302 | I6: Açık
A7: U-03 | B7: 46295 | C7: Kimlik belgesi | D7: Tesis sorumlusu alanı boş. | E7: B sınıfı kadro atanmamış. | F7: Atama ve kimlik güncellemesi. Y-03. | G7: İşletme | H7: 46326 | I7: Açık
A8: U-04 | B8: 46269 | C8: İç tetkik 6.3.7 | D8: Atık sözleşmesi yok. Çamur analizi yok. | E8: Bertaraf firması bağlanmamış, kod analizsiz seçilmiş. | F8: Sözleşme ve karakterizasyon. Y-04. | G8: Danışman + işletme | H8: 46326 | I8: Açık
A9: U-05
A10: U-06
A11: U-07
A12: U-08
A13: U-09
A14: U-10
A15: U-11
A16: U-12
A17: U-13
A18: U-14
A19: U-15
A20: U-16
... A34: U-30

Sheet Notlar
A1: DANIŞMAN NOTLARI
A2: Bu notlar 30.09.2026’da dört belge okunarak yazıldı. Saha ölçümü, analiz ve e-İzin eki yoktur.
A4: 1 | B4: Uygunluk iddiası ancak analiz raporu ve debi ile kurulur. Eylül 2026 numunesi ‘alındı’ cümlesi sonuç değildir.
A5: 2 | B5: Evsel debi büyük olsa da Tablo 21 uygulanmaz. Evsel ve endüstriyel su birlikte arıtıldığı için standart Tablo 5.9’dur.
A6: 3 | B6: Tablo 5.9’da BOİ ve yağ-gres yoktur. Yasal kıyas KOİ, AKM ve pH iledir. Mum kaynaklı yağ işletmeyi bozarsa ölçülür; limite kendiliğinden eklenmez.
A7: 4 | B7: Denetim numunesi normal işletmede alınan, debiyle orantılı iki saatlik kompozittir. İki saatten kısa deşarjda, deşarj süresi boyunca alınan kompozit bu limite kıyaslanır.
A8: 5 | B8: Anlık numune kontrol amaçlıdır. KOİ veya AKM anlık sonucu limiti yüzde 20’den fazla aşarsa yaptırıma esas değerlendirilir. pH için 6-9 aynen uygulanır, yüzde 20 payı yoktur.
A9: 6 | B9: İç izleme limiti aşarsa il müdürlüğüne haber verilir. Numune tarihinden itibaren on iş günü içinde iki numune daha alınır. Üç sonucun ortalaması limite uyuyorsa cezai işlem uygulanmaz.
A10: 7 | B10: Bu sektörde düşürülecek ekstra parametre yoktur. İlk yıl üç uygun sonuç gelse de KOİ, AKM ve pH her kampanyada bakılır.
A11: 8 | B11: Fiili debi 51-200 m³/gün ise iç izleme iki ayda bir, ilin denetime esas asgari sıklığı altı ayda birdir. Sürekli 50 ve altında dört aya inmek il müdürlüğünün yazısını gerektirir.
A12: 9 | B12: 90 m³/gün için SAİS, otomatik numune alma cihazı ve sürekli debi ölçer bu hükümle zorunlu değildir. Temsil edici numune noktası ve yazılı debi zorunlu iştir.
A13: 10 | B13: Çevre görevlisi, B sınıfı tesis sorumlusunun yerine geçmez. Kimlikteki boş alan kapatılmadan personel yükümlülüğü tamamlanmış sayılmaz.
A14: 11 | B14: 19 08 13* kodu analiz olmadan hem yükümlülüğü ağırlaştırır hem denetimde sorgulanır. Analizden önce kodu tehlikesize çevirmeyin.
A15: 12 | B15: Yıkama suyunu yağmur suyuyla aynı hatta verip dereye basmak arıtılmamış deşarjdır. İç tetkikteki 6.1.4 cümlesi bu yüzden önce sahada kapatılır.
... A21: 18 | B21: Bu çalışma notu idari işlem, izin belgesi veya uygunluk beyanı değildir.

Sheet _Listeler
A1: Açık | B1: Kritik | C1: Uygun | D1: Evet | E1: 2 saatlik kompozit
A2: Devam ediyor | B2: Yüksek | C2: Uygun değil | D2: Hayır | E2: Deşarj süresi kompoziti
A3: Beklemede | B3: Orta | C3: Gözlenmedi | E3: Anlık (kontrol)
A4: Tamamlandı | B4: Düşük | C4: Kapsam dışı
